[2021-04-08T15:01:16+0800] [WARNING] [root] [pid:36672] [middleware.py:81] Traceback (most recent call last):
  File "/Users/xzr/.virtualenvs/djmyframework/lib/python3.7/site-packages/django/core/handlers/base.py", line 113, in _get_response
    response = wrapped_callback(request, *callback_args, **callback_kwargs)
  File "/Users/xzr/.virtualenvs/djmyframework/lib/python3.7/site-packages/django/views/decorators/csrf.py", line 54, in wrapped_view
    return view_func(*args, **kwargs)
  File "/Users/xzr/.virtualenvs/djmyframework/lib/python3.7/site-packages/django/views/generic/base.py", line 71, in view
    return self.dispatch(request, *args, **kwargs)
  File "/Users/xzr/.virtualenvs/djmyframework/lib/python3.7/site-packages/rest_framework/views.py", line 509, in dispatch
    response = self.handle_exception(exc)
  File "/Users/xzr/.virtualenvs/djmyframework/lib/python3.7/site-packages/rest_framework/views.py", line 469, in handle_exception
    self.raise_uncaught_exception(exc)
  File "/Users/xzr/.virtualenvs/djmyframework/lib/python3.7/site-packages/rest_framework/views.py", line 480, in raise_uncaught_exception
    raise exc
  File "/Users/xzr/.virtualenvs/djmyframework/lib/python3.7/site-packages/rest_framework/views.py", line 506, in dispatch
    response = handler(request, *args, **kwargs)
  File "/Users/xzr/Desktop/pipy/djmyframework/djmyframework/framework/views.py", line 179, in handler
    return func(*args, **kwargs)
  File "/Users/xzr/Desktop/pipy/djmyframework/djmyframework/apps/myadmin/views/__init__.py", line 120, in login
    the_user = ldap_login(request, username, password)
  File "/Users/xzr/Desktop/pipy/djmyframework/djmyframework/apps/myadmin/views/__init__.py", line 91, in ldap_login
    the_user.is_ldap = True
AttributeError: 'NoneType' object has no attribute 'is_ldap'

[2021-04-08T15:01:16+0800] [ERROR] [django.request] [pid:36672] [log.py:228] Internal Server Error: /myadmin/login
Traceback (most recent call last):
  File "/Users/xzr/.virtualenvs/djmyframework/lib/python3.7/site-packages/django/core/handlers/exception.py", line 34, in inner
    response = get_response(request)
  File "/Users/xzr/.virtualenvs/djmyframework/lib/python3.7/site-packages/django/core/handlers/base.py", line 115, in _get_response
    response = self.process_exception_by_middleware(e, request)
  File "/Users/xzr/.virtualenvs/djmyframework/lib/python3.7/site-packages/django/core/handlers/base.py", line 113, in _get_response
    response = wrapped_callback(request, *callback_args, **callback_kwargs)
  File "/Users/xzr/.virtualenvs/djmyframework/lib/python3.7/site-packages/django/views/decorators/csrf.py", line 54, in wrapped_view
    return view_func(*args, **kwargs)
  File "/Users/xzr/.virtualenvs/djmyframework/lib/python3.7/site-packages/django/views/generic/base.py", line 71, in view
    return self.dispatch(request, *args, **kwargs)
  File "/Users/xzr/.virtualenvs/djmyframework/lib/python3.7/site-packages/rest_framework/views.py", line 509, in dispatch
    response = self.handle_exception(exc)
  File "/Users/xzr/.virtualenvs/djmyframework/lib/python3.7/site-packages/rest_framework/views.py", line 469, in handle_exception
    self.raise_uncaught_exception(exc)
  File "/Users/xzr/.virtualenvs/djmyframework/lib/python3.7/site-packages/rest_framework/views.py", line 480, in raise_uncaught_exception
    raise exc
  File "/Users/xzr/.virtualenvs/djmyframework/lib/python3.7/site-packages/rest_framework/views.py", line 506, in dispatch
    response = handler(request, *args, **kwargs)
  File "/Users/xzr/Desktop/pipy/djmyframework/djmyframework/framework/views.py", line 179, in handler
    return func(*args, **kwargs)
  File "/Users/xzr/Desktop/pipy/djmyframework/djmyframework/apps/myadmin/views/__init__.py", line 120, in login
    the_user = ldap_login(request, username, password)
  File "/Users/xzr/Desktop/pipy/djmyframework/djmyframework/apps/myadmin/views/__init__.py", line 91, in ldap_login
    the_user.is_ldap = True
AttributeError: 'NoneType' object has no attribute 'is_ldap'
[2021-04-08T15:11:03+0800] [WARNING] [root] [pid:36933] [middleware.py:81] Traceback (most recent call last):
  File "/Users/xzr/.virtualenvs/djmyframework/lib/python3.7/site-packages/django/core/handlers/base.py", line 113, in _get_response
    response = wrapped_callback(request, *callback_args, **callback_kwargs)
  File "/Users/xzr/.virtualenvs/djmyframework/lib/python3.7/site-packages/django/views/decorators/csrf.py", line 54, in wrapped_view
    return view_func(*args, **kwargs)
  File "/Users/xzr/.virtualenvs/djmyframework/lib/python3.7/site-packages/rest_framework/viewsets.py", line 125, in view
    return self.dispatch(request, *args, **kwargs)
  File "/Users/xzr/.virtualenvs/djmyframework/lib/python3.7/site-packages/rest_framework/views.py", line 509, in dispatch
    response = self.handle_exception(exc)
  File "/Users/xzr/.virtualenvs/djmyframework/lib/python3.7/site-packages/rest_framework/views.py", line 469, in handle_exception
    self.raise_uncaught_exception(exc)
  File "/Users/xzr/.virtualenvs/djmyframework/lib/python3.7/site-packages/rest_framework/views.py", line 480, in raise_uncaught_exception
    raise exc
  File "/Users/xzr/.virtualenvs/djmyframework/lib/python3.7/site-packages/rest_framework/views.py", line 506, in dispatch
    response = handler(request, *args, **kwargs)
  File "/Users/xzr/Desktop/pipy/djmyframework/djmyframework/apps/ldap_account/views/access_domain.py", line 58, in list
    return rt("ldap_account/access_domain/list.html", super().list(request))
  File "/Users/xzr/Desktop/pipy/djmyframework/djmyframework/framework/views.py", line 426, in list
    return self.get_paginated_response(serializer.data)
  File "/Users/xzr/.virtualenvs/djmyframework/lib/python3.7/site-packages/rest_framework/serializers.py", line 745, in data
    ret = super().data
  File "/Users/xzr/.virtualenvs/djmyframework/lib/python3.7/site-packages/rest_framework/serializers.py", line 246, in data
    self._data = self.to_representation(self.instance)
  File "/Users/xzr/.virtualenvs/djmyframework/lib/python3.7/site-packages/rest_framework/serializers.py", line 664, in to_representation
    self.child.to_representation(item) for item in iterable
  File "/Users/xzr/.virtualenvs/djmyframework/lib/python3.7/site-packages/rest_framework/serializers.py", line 664, in <listcomp>
    self.child.to_representation(item) for item in iterable
  File "/Users/xzr/.virtualenvs/djmyframework/lib/python3.7/site-packages/rest_framework/serializers.py", line 502, in to_representation
    attribute = field.get_attribute(instance)
  File "/Users/xzr/.virtualenvs/djmyframework/lib/python3.7/site-packages/rest_framework/fields.py", line 457, in get_attribute
    return get_attribute(instance, self.source_attrs)
  File "/Users/xzr/.virtualenvs/djmyframework/lib/python3.7/site-packages/rest_framework/fields.py", line 97, in get_attribute
    instance = getattr(instance, attr)
  File "/Users/xzr/Desktop/pipy/djmyframework/djmyframework/apps/ldap_account/models.py", line 102, in authdn
    return 'cn=%s,ou=people' % (self.name,self.basedn)
TypeError: not all arguments converted during string formatting

[2021-04-08T15:11:03+0800] [ERROR] [django.request] [pid:36933] [log.py:228] Internal Server Error: /ldap_account/access_domain/list
[2021-04-09T11:47:03+0800] [WARNING] [root] [pid:48810] [middleware.py:81] Traceback (most recent call last):
  File "/Users/xzr/.virtualenvs/djmyframework/lib/python3.7/site-packages/django/core/handlers/base.py", line 143, in _get_response
    response = response.render()
  File "/Users/xzr/.virtualenvs/djmyframework/lib/python3.7/site-packages/django/template/response.py", line 105, in render
    self.content = self.rendered_content
  File "/Users/xzr/Desktop/pipy/djmyframework/djmyframework/framework/response.py", line 107, in rendered_content
    return super(Response, self).rendered_content
  File "/Users/xzr/.virtualenvs/djmyframework/lib/python3.7/site-packages/rest_framework/response.py", line 70, in rendered_content
    ret = renderer.render(self.data, accepted_media_type, context)
  File "/Users/xzr/.virtualenvs/djmyframework/lib/python3.7/site-packages/rest_framework/renderers.py", line 103, in render
    allow_nan=not self.strict, separators=separators
  File "/Users/xzr/.virtualenvs/djmyframework/lib/python3.7/site-packages/rest_framework/utils/json.py", line 25, in dumps
    return json.dumps(*args, **kwargs)
  File "/Library/Frameworks/Python.framework/Versions/3.7/lib/python3.7/json/__init__.py", line 238, in dumps
    **kw).encode(obj)
  File "/Library/Frameworks/Python.framework/Versions/3.7/lib/python3.7/json/encoder.py", line 199, in encode
    chunks = self.iterencode(o, _one_shot=True)
  File "/Library/Frameworks/Python.framework/Versions/3.7/lib/python3.7/json/encoder.py", line 257, in iterencode
    return _iterencode(o, 0)
  File "/Users/xzr/Desktop/pipy/djmyframework/djmyframework/framework/utils/__init__.py", line 118, in default
    return super(MyJsonEncoder, self).default(obj)
  File "/Users/xzr/.virtualenvs/djmyframework/lib/python3.7/site-packages/rest_framework/utils/encoders.py", line 67, in default
    return super().default(obj)
  File "/Library/Frameworks/Python.framework/Versions/3.7/lib/python3.7/json/encoder.py", line 179, in default
    raise TypeError(f'Object of type {o.__class__.__name__} '
TypeError: Object of type type is not JSON serializable

[2021-04-09T11:47:04+0800] [ERROR] [django.request] [pid:48810] [log.py:228] Internal Server Error: /myadmin/menu/update_menu
Traceback (most recent call last):
  File "/Users/xzr/.virtualenvs/djmyframework/lib/python3.7/site-packages/django/core/handlers/exception.py", line 34, in inner
    response = get_response(request)
  File "/Users/xzr/.virtualenvs/djmyframework/lib/python3.7/site-packages/django/core/handlers/base.py", line 145, in _get_response
    response = self.process_exception_by_middleware(e, request)
  File "/Users/xzr/.virtualenvs/djmyframework/lib/python3.7/site-packages/django/core/handlers/base.py", line 143, in _get_response
    response = response.render()
  File "/Users/xzr/.virtualenvs/djmyframework/lib/python3.7/site-packages/django/template/response.py", line 105, in render
    self.content = self.rendered_content
  File "/Users/xzr/Desktop/pipy/djmyframework/djmyframework/framework/response.py", line 107, in rendered_content
    return super(Response, self).rendered_content
  File "/Users/xzr/.virtualenvs/djmyframework/lib/python3.7/site-packages/rest_framework/response.py", line 70, in rendered_content
    ret = renderer.render(self.data, accepted_media_type, context)
  File "/Users/xzr/.virtualenvs/djmyframework/lib/python3.7/site-packages/rest_framework/renderers.py", line 103, in render
    allow_nan=not self.strict, separators=separators
  File "/Users/xzr/.virtualenvs/djmyframework/lib/python3.7/site-packages/rest_framework/utils/json.py", line 25, in dumps
    return json.dumps(*args, **kwargs)
  File "/Library/Frameworks/Python.framework/Versions/3.7/lib/python3.7/json/__init__.py", line 238, in dumps
    **kw).encode(obj)
  File "/Library/Frameworks/Python.framework/Versions/3.7/lib/python3.7/json/encoder.py", line 199, in encode
    chunks = self.iterencode(o, _one_shot=True)
  File "/Library/Frameworks/Python.framework/Versions/3.7/lib/python3.7/json/encoder.py", line 257, in iterencode
    return _iterencode(o, 0)
  File "/Users/xzr/Desktop/pipy/djmyframework/djmyframework/framework/utils/__init__.py", line 118, in default
    return super(MyJsonEncoder, self).default(obj)
  File "/Users/xzr/.virtualenvs/djmyframework/lib/python3.7/site-packages/rest_framework/utils/encoders.py", line 67, in default
    return super().default(obj)
  File "/Library/Frameworks/Python.framework/Versions/3.7/lib/python3.7/json/encoder.py", line 179, in default
    raise TypeError(f'Object of type {o.__class__.__name__} '
TypeError: Object of type type is not JSON serializable
[2021-04-09T11:47:34+0800] [WARNING] [root] [pid:48810] [middleware.py:81] Traceback (most recent call last):
  File "/Users/xzr/.virtualenvs/djmyframework/lib/python3.7/site-packages/django/core/handlers/base.py", line 143, in _get_response
    response = response.render()
  File "/Users/xzr/.virtualenvs/djmyframework/lib/python3.7/site-packages/django/template/response.py", line 105, in render
    self.content = self.rendered_content
  File "/Users/xzr/Desktop/pipy/djmyframework/djmyframework/framework/response.py", line 107, in rendered_content
    return super(Response, self).rendered_content
  File "/Users/xzr/.virtualenvs/djmyframework/lib/python3.7/site-packages/rest_framework/response.py", line 70, in rendered_content
    ret = renderer.render(self.data, accepted_media_type, context)
  File "/Users/xzr/.virtualenvs/djmyframework/lib/python3.7/site-packages/rest_framework/renderers.py", line 103, in render
    allow_nan=not self.strict, separators=separators
  File "/Users/xzr/.virtualenvs/djmyframework/lib/python3.7/site-packages/rest_framework/utils/json.py", line 25, in dumps
    return json.dumps(*args, **kwargs)
  File "/Library/Frameworks/Python.framework/Versions/3.7/lib/python3.7/json/__init__.py", line 238, in dumps
    **kw).encode(obj)
  File "/Library/Frameworks/Python.framework/Versions/3.7/lib/python3.7/json/encoder.py", line 199, in encode
    chunks = self.iterencode(o, _one_shot=True)
  File "/Library/Frameworks/Python.framework/Versions/3.7/lib/python3.7/json/encoder.py", line 257, in iterencode
    return _iterencode(o, 0)
  File "/Users/xzr/Desktop/pipy/djmyframework/djmyframework/framework/utils/__init__.py", line 118, in default
    return super(MyJsonEncoder, self).default(obj)
  File "/Users/xzr/.virtualenvs/djmyframework/lib/python3.7/site-packages/rest_framework/utils/encoders.py", line 67, in default
    return super().default(obj)
  File "/Library/Frameworks/Python.framework/Versions/3.7/lib/python3.7/json/encoder.py", line 179, in default
    raise TypeError(f'Object of type {o.__class__.__name__} '
TypeError: Object of type type is not JSON serializable

[2021-04-09T11:47:35+0800] [ERROR] [django.request] [pid:48810] [log.py:228] Internal Server Error: /myadmin/menu/update_menu
Traceback (most recent call last):
  File "/Users/xzr/.virtualenvs/djmyframework/lib/python3.7/site-packages/django/core/handlers/exception.py", line 34, in inner
    response = get_response(request)
  File "/Users/xzr/.virtualenvs/djmyframework/lib/python3.7/site-packages/django/core/handlers/base.py", line 145, in _get_response
    response = self.process_exception_by_middleware(e, request)
  File "/Users/xzr/.virtualenvs/djmyframework/lib/python3.7/site-packages/django/core/handlers/base.py", line 143, in _get_response
    response = response.render()
  File "/Users/xzr/.virtualenvs/djmyframework/lib/python3.7/site-packages/django/template/response.py", line 105, in render
    self.content = self.rendered_content
  File "/Users/xzr/Desktop/pipy/djmyframework/djmyframework/framework/response.py", line 107, in rendered_content
    return super(Response, self).rendered_content
  File "/Users/xzr/.virtualenvs/djmyframework/lib/python3.7/site-packages/rest_framework/response.py", line 70, in rendered_content
    ret = renderer.render(self.data, accepted_media_type, context)
  File "/Users/xzr/.virtualenvs/djmyframework/lib/python3.7/site-packages/rest_framework/renderers.py", line 103, in render
    allow_nan=not self.strict, separators=separators
  File "/Users/xzr/.virtualenvs/djmyframework/lib/python3.7/site-packages/rest_framework/utils/json.py", line 25, in dumps
    return json.dumps(*args, **kwargs)
  File "/Library/Frameworks/Python.framework/Versions/3.7/lib/python3.7/json/__init__.py", line 238, in dumps
    **kw).encode(obj)
  File "/Library/Frameworks/Python.framework/Versions/3.7/lib/python3.7/json/encoder.py", line 199, in encode
    chunks = self.iterencode(o, _one_shot=True)
  File "/Library/Frameworks/Python.framework/Versions/3.7/lib/python3.7/json/encoder.py", line 257, in iterencode
    return _iterencode(o, 0)
  File "/Users/xzr/Desktop/pipy/djmyframework/djmyframework/framework/utils/__init__.py", line 118, in default
    return super(MyJsonEncoder, self).default(obj)
  File "/Users/xzr/.virtualenvs/djmyframework/lib/python3.7/site-packages/rest_framework/utils/encoders.py", line 67, in default
    return super().default(obj)
  File "/Library/Frameworks/Python.framework/Versions/3.7/lib/python3.7/json/encoder.py", line 179, in default
    raise TypeError(f'Object of type {o.__class__.__name__} '
TypeError: Object of type type is not JSON serializable
[2021-04-09T11:48:03+0800] [WARNING] [root] [pid:48828] [middleware.py:81] Traceback (most recent call last):
  File "/Users/xzr/.virtualenvs/djmyframework/lib/python3.7/site-packages/django/core/handlers/base.py", line 143, in _get_response
    response = response.render()
  File "/Users/xzr/.virtualenvs/djmyframework/lib/python3.7/site-packages/django/template/response.py", line 105, in render
    self.content = self.rendered_content
  File "/Users/xzr/Desktop/pipy/djmyframework/djmyframework/framework/response.py", line 107, in rendered_content
    return super(Response, self).rendered_content
  File "/Users/xzr/.virtualenvs/djmyframework/lib/python3.7/site-packages/rest_framework/response.py", line 70, in rendered_content
    ret = renderer.render(self.data, accepted_media_type, context)
  File "/Users/xzr/.virtualenvs/djmyframework/lib/python3.7/site-packages/rest_framework/renderers.py", line 103, in render
    allow_nan=not self.strict, separators=separators
  File "/Users/xzr/.virtualenvs/djmyframework/lib/python3.7/site-packages/rest_framework/utils/json.py", line 25, in dumps
    return json.dumps(*args, **kwargs)
  File "/Library/Frameworks/Python.framework/Versions/3.7/lib/python3.7/json/__init__.py", line 238, in dumps
    **kw).encode(obj)
  File "/Library/Frameworks/Python.framework/Versions/3.7/lib/python3.7/json/encoder.py", line 199, in encode
    chunks = self.iterencode(o, _one_shot=True)
  File "/Library/Frameworks/Python.framework/Versions/3.7/lib/python3.7/json/encoder.py", line 257, in iterencode
    return _iterencode(o, 0)
  File "/Users/xzr/Desktop/pipy/djmyframework/djmyframework/framework/utils/__init__.py", line 118, in default
    return super(MyJsonEncoder, self).default(obj)
  File "/Users/xzr/.virtualenvs/djmyframework/lib/python3.7/site-packages/rest_framework/utils/encoders.py", line 67, in default
    return super().default(obj)
  File "/Library/Frameworks/Python.framework/Versions/3.7/lib/python3.7/json/encoder.py", line 179, in default
    raise TypeError(f'Object of type {o.__class__.__name__} '
TypeError: Object of type type is not JSON serializable

[2021-04-09T11:48:04+0800] [ERROR] [django.request] [pid:48828] [log.py:228] Internal Server Error: /myadmin/menu/update_menu
Traceback (most recent call last):
  File "/Users/xzr/.virtualenvs/djmyframework/lib/python3.7/site-packages/django/core/handlers/exception.py", line 34, in inner
    response = get_response(request)
  File "/Users/xzr/.virtualenvs/djmyframework/lib/python3.7/site-packages/django/core/handlers/base.py", line 145, in _get_response
    response = self.process_exception_by_middleware(e, request)
  File "/Users/xzr/.virtualenvs/djmyframework/lib/python3.7/site-packages/django/core/handlers/base.py", line 143, in _get_response
    response = response.render()
  File "/Users/xzr/.virtualenvs/djmyframework/lib/python3.7/site-packages/django/template/response.py", line 105, in render
    self.content = self.rendered_content
  File "/Users/xzr/Desktop/pipy/djmyframework/djmyframework/framework/response.py", line 107, in rendered_content
    return super(Response, self).rendered_content
  File "/Users/xzr/.virtualenvs/djmyframework/lib/python3.7/site-packages/rest_framework/response.py", line 70, in rendered_content
    ret = renderer.render(self.data, accepted_media_type, context)
  File "/Users/xzr/.virtualenvs/djmyframework/lib/python3.7/site-packages/rest_framework/renderers.py", line 103, in render
    allow_nan=not self.strict, separators=separators
  File "/Users/xzr/.virtualenvs/djmyframework/lib/python3.7/site-packages/rest_framework/utils/json.py", line 25, in dumps
    return json.dumps(*args, **kwargs)
  File "/Library/Frameworks/Python.framework/Versions/3.7/lib/python3.7/json/__init__.py", line 238, in dumps
    **kw).encode(obj)
  File "/Library/Frameworks/Python.framework/Versions/3.7/lib/python3.7/json/encoder.py", line 199, in encode
    chunks = self.iterencode(o, _one_shot=True)
  File "/Library/Frameworks/Python.framework/Versions/3.7/lib/python3.7/json/encoder.py", line 257, in iterencode
    return _iterencode(o, 0)
  File "/Users/xzr/Desktop/pipy/djmyframework/djmyframework/framework/utils/__init__.py", line 118, in default
    return super(MyJsonEncoder, self).default(obj)
  File "/Users/xzr/.virtualenvs/djmyframework/lib/python3.7/site-packages/rest_framework/utils/encoders.py", line 67, in default
    return super().default(obj)
  File "/Library/Frameworks/Python.framework/Versions/3.7/lib/python3.7/json/encoder.py", line 179, in default
    raise TypeError(f'Object of type {o.__class__.__name__} '
TypeError: Object of type type is not JSON serializable
[2021-04-09T11:48:34+0800] [WARNING] [root] [pid:48848] [middleware.py:81] Traceback (most recent call last):
  File "/Users/xzr/.virtualenvs/djmyframework/lib/python3.7/site-packages/django/core/handlers/base.py", line 143, in _get_response
    response = response.render()
  File "/Users/xzr/.virtualenvs/djmyframework/lib/python3.7/site-packages/django/template/response.py", line 105, in render
    self.content = self.rendered_content
  File "/Users/xzr/Desktop/pipy/djmyframework/djmyframework/framework/response.py", line 107, in rendered_content
    return super(Response, self).rendered_content
  File "/Users/xzr/.virtualenvs/djmyframework/lib/python3.7/site-packages/rest_framework/response.py", line 70, in rendered_content
    ret = renderer.render(self.data, accepted_media_type, context)
  File "/Users/xzr/.virtualenvs/djmyframework/lib/python3.7/site-packages/rest_framework/renderers.py", line 103, in render
    allow_nan=not self.strict, separators=separators
  File "/Users/xzr/.virtualenvs/djmyframework/lib/python3.7/site-packages/rest_framework/utils/json.py", line 25, in dumps
    return json.dumps(*args, **kwargs)
  File "/Library/Frameworks/Python.framework/Versions/3.7/lib/python3.7/json/__init__.py", line 238, in dumps
    **kw).encode(obj)
  File "/Library/Frameworks/Python.framework/Versions/3.7/lib/python3.7/json/encoder.py", line 199, in encode
    chunks = self.iterencode(o, _one_shot=True)
  File "/Library/Frameworks/Python.framework/Versions/3.7/lib/python3.7/json/encoder.py", line 257, in iterencode
    return _iterencode(o, 0)
  File "/Users/xzr/Desktop/pipy/djmyframework/djmyframework/framework/utils/__init__.py", line 118, in default
    return super(MyJsonEncoder, self).default(obj)
  File "/Users/xzr/.virtualenvs/djmyframework/lib/python3.7/site-packages/rest_framework/utils/encoders.py", line 67, in default
    return super().default(obj)
  File "/Library/Frameworks/Python.framework/Versions/3.7/lib/python3.7/json/encoder.py", line 179, in default
    raise TypeError(f'Object of type {o.__class__.__name__} '
TypeError: Object of type type is not JSON serializable

[2021-04-09T11:48:35+0800] [ERROR] [django.request] [pid:48848] [log.py:228] Internal Server Error: /myadmin/menu/update_menu
Traceback (most recent call last):
  File "/Users/xzr/.virtualenvs/djmyframework/lib/python3.7/site-packages/django/core/handlers/exception.py", line 34, in inner
    response = get_response(request)
  File "/Users/xzr/.virtualenvs/djmyframework/lib/python3.7/site-packages/django/core/handlers/base.py", line 145, in _get_response
    response = self.process_exception_by_middleware(e, request)
  File "/Users/xzr/.virtualenvs/djmyframework/lib/python3.7/site-packages/django/core/handlers/base.py", line 143, in _get_response
    response = response.render()
  File "/Users/xzr/.virtualenvs/djmyframework/lib/python3.7/site-packages/django/template/response.py", line 105, in render
    self.content = self.rendered_content
  File "/Users/xzr/Desktop/pipy/djmyframework/djmyframework/framework/response.py", line 107, in rendered_content
    return super(Response, self).rendered_content
  File "/Users/xzr/.virtualenvs/djmyframework/lib/python3.7/site-packages/rest_framework/response.py", line 70, in rendered_content
    ret = renderer.render(self.data, accepted_media_type, context)
  File "/Users/xzr/.virtualenvs/djmyframework/lib/python3.7/site-packages/rest_framework/renderers.py", line 103, in render
    allow_nan=not self.strict, separators=separators
  File "/Users/xzr/.virtualenvs/djmyframework/lib/python3.7/site-packages/rest_framework/utils/json.py", line 25, in dumps
    return json.dumps(*args, **kwargs)
  File "/Library/Frameworks/Python.framework/Versions/3.7/lib/python3.7/json/__init__.py", line 238, in dumps
    **kw).encode(obj)
  File "/Library/Frameworks/Python.framework/Versions/3.7/lib/python3.7/json/encoder.py", line 199, in encode
    chunks = self.iterencode(o, _one_shot=True)
  File "/Library/Frameworks/Python.framework/Versions/3.7/lib/python3.7/json/encoder.py", line 257, in iterencode
    return _iterencode(o, 0)
  File "/Users/xzr/Desktop/pipy/djmyframework/djmyframework/framework/utils/__init__.py", line 118, in default
    return super(MyJsonEncoder, self).default(obj)
  File "/Users/xzr/.virtualenvs/djmyframework/lib/python3.7/site-packages/rest_framework/utils/encoders.py", line 67, in default
    return super().default(obj)
  File "/Library/Frameworks/Python.framework/Versions/3.7/lib/python3.7/json/encoder.py", line 179, in default
    raise TypeError(f'Object of type {o.__class__.__name__} '
TypeError: Object of type type is not JSON serializable
[2021-04-09T11:48:36+0800] [WARNING] [root] [pid:48848] [middleware.py:81] Traceback (most recent call last):
  File "/Users/xzr/.virtualenvs/djmyframework/lib/python3.7/site-packages/django/core/handlers/base.py", line 143, in _get_response
    response = response.render()
  File "/Users/xzr/.virtualenvs/djmyframework/lib/python3.7/site-packages/django/template/response.py", line 105, in render
    self.content = self.rendered_content
  File "/Users/xzr/Desktop/pipy/djmyframework/djmyframework/framework/response.py", line 107, in rendered_content
    return super(Response, self).rendered_content
  File "/Users/xzr/.virtualenvs/djmyframework/lib/python3.7/site-packages/rest_framework/response.py", line 70, in rendered_content
    ret = renderer.render(self.data, accepted_media_type, context)
  File "/Users/xzr/.virtualenvs/djmyframework/lib/python3.7/site-packages/rest_framework/renderers.py", line 103, in render
    allow_nan=not self.strict, separators=separators
  File "/Users/xzr/.virtualenvs/djmyframework/lib/python3.7/site-packages/rest_framework/utils/json.py", line 25, in dumps
    return json.dumps(*args, **kwargs)
  File "/Library/Frameworks/Python.framework/Versions/3.7/lib/python3.7/json/__init__.py", line 238, in dumps
    **kw).encode(obj)
  File "/Library/Frameworks/Python.framework/Versions/3.7/lib/python3.7/json/encoder.py", line 199, in encode
    chunks = self.iterencode(o, _one_shot=True)
  File "/Library/Frameworks/Python.framework/Versions/3.7/lib/python3.7/json/encoder.py", line 257, in iterencode
    return _iterencode(o, 0)
  File "/Users/xzr/Desktop/pipy/djmyframework/djmyframework/framework/utils/__init__.py", line 118, in default
    return super(MyJsonEncoder, self).default(obj)
  File "/Users/xzr/.virtualenvs/djmyframework/lib/python3.7/site-packages/rest_framework/utils/encoders.py", line 67, in default
    return super().default(obj)
  File "/Library/Frameworks/Python.framework/Versions/3.7/lib/python3.7/json/encoder.py", line 179, in default
    raise TypeError(f'Object of type {o.__class__.__name__} '
TypeError: Object of type type is not JSON serializable

[2021-04-09T11:48:36+0800] [ERROR] [django.request] [pid:48848] [log.py:228] Internal Server Error: /myadmin/menu/update_menu
Traceback (most recent call last):
  File "/Users/xzr/.virtualenvs/djmyframework/lib/python3.7/site-packages/django/core/handlers/exception.py", line 34, in inner
    response = get_response(request)
  File "/Users/xzr/.virtualenvs/djmyframework/lib/python3.7/site-packages/django/core/handlers/base.py", line 145, in _get_response
    response = self.process_exception_by_middleware(e, request)
  File "/Users/xzr/.virtualenvs/djmyframework/lib/python3.7/site-packages/django/core/handlers/base.py", line 143, in _get_response
    response = response.render()
  File "/Users/xzr/.virtualenvs/djmyframework/lib/python3.7/site-packages/django/template/response.py", line 105, in render
    self.content = self.rendered_content
  File "/Users/xzr/Desktop/pipy/djmyframework/djmyframework/framework/response.py", line 107, in rendered_content
    return super(Response, self).rendered_content
  File "/Users/xzr/.virtualenvs/djmyframework/lib/python3.7/site-packages/rest_framework/response.py", line 70, in rendered_content
    ret = renderer.render(self.data, accepted_media_type, context)
  File "/Users/xzr/.virtualenvs/djmyframework/lib/python3.7/site-packages/rest_framework/renderers.py", line 103, in render
    allow_nan=not self.strict, separators=separators
  File "/Users/xzr/.virtualenvs/djmyframework/lib/python3.7/site-packages/rest_framework/utils/json.py", line 25, in dumps
    return json.dumps(*args, **kwargs)
  File "/Library/Frameworks/Python.framework/Versions/3.7/lib/python3.7/json/__init__.py", line 238, in dumps
    **kw).encode(obj)
  File "/Library/Frameworks/Python.framework/Versions/3.7/lib/python3.7/json/encoder.py", line 199, in encode
    chunks = self.iterencode(o, _one_shot=True)
  File "/Library/Frameworks/Python.framework/Versions/3.7/lib/python3.7/json/encoder.py", line 257, in iterencode
    return _iterencode(o, 0)
  File "/Users/xzr/Desktop/pipy/djmyframework/djmyframework/framework/utils/__init__.py", line 118, in default
    return super(MyJsonEncoder, self).default(obj)
  File "/Users/xzr/.virtualenvs/djmyframework/lib/python3.7/site-packages/rest_framework/utils/encoders.py", line 67, in default
    return super().default(obj)
  File "/Library/Frameworks/Python.framework/Versions/3.7/lib/python3.7/json/encoder.py", line 179, in default
    raise TypeError(f'Object of type {o.__class__.__name__} '
TypeError: Object of type type is not JSON serializable
[2021-04-09T12:17:23+0800] [WARNING] [root] [pid:49254] [middleware.py:81] Traceback (most recent call last):
  File "/Users/xzr/Desktop/pipy/djmyframework/djmyframework/apps/myadmin/models/menu.py", line 250, in create_menu_from_config
    selfId, parentId, order = cls.getIdAndParentId(mc.von)  # 处理获得id，父id，排序
  File "/Users/xzr/Desktop/pipy/djmyframework/djmyframework/apps/myadmin/models/menu.py", line 290, in getIdAndParentId
    return selfId, int(parentId), order
TypeError: int() argument must be a string, a bytes-like object or a number, not 'NoneType'

During handling of the above exception, another exception occurred:

Traceback (most recent call last):
  File "/Users/xzr/.virtualenvs/djmyframework/lib/python3.7/site-packages/django/core/handlers/base.py", line 113, in _get_response
    response = wrapped_callback(request, *callback_args, **callback_kwargs)
  File "/Users/xzr/.virtualenvs/djmyframework/lib/python3.7/site-packages/django/views/decorators/csrf.py", line 54, in wrapped_view
    return view_func(*args, **kwargs)
  File "/Users/xzr/.virtualenvs/djmyframework/lib/python3.7/site-packages/rest_framework/viewsets.py", line 125, in view
    return self.dispatch(request, *args, **kwargs)
  File "/Users/xzr/.virtualenvs/djmyframework/lib/python3.7/site-packages/rest_framework/views.py", line 509, in dispatch
    response = self.handle_exception(exc)
  File "/Users/xzr/.virtualenvs/djmyframework/lib/python3.7/site-packages/rest_framework/views.py", line 469, in handle_exception
    self.raise_uncaught_exception(exc)
  File "/Users/xzr/.virtualenvs/djmyframework/lib/python3.7/site-packages/rest_framework/views.py", line 480, in raise_uncaught_exception
    raise exc
  File "/Users/xzr/.virtualenvs/djmyframework/lib/python3.7/site-packages/rest_framework/views.py", line 506, in dispatch
    response = handler(request, *args, **kwargs)
  File "/Users/xzr/Desktop/pipy/djmyframework/djmyframework/apps/myadmin/views/menu.py", line 110, in update_menu
    MenuConfig.create_menu_from_config(add_mc_list)
  File "/Users/xzr/Desktop/pipy/djmyframework/djmyframework/framework/utils/single_process.py", line 56, in wrapper
    return f(*args, **kwargs)
  File "/Users/xzr/Desktop/pipy/djmyframework/djmyframework/apps/myadmin/models/menu.py", line 275, in create_menu_from_config
    raise Exception
Exception

[2021-04-09T12:17:24+0800] [ERROR] [django.request] [pid:49254] [log.py:228] Internal Server Error: /myadmin/menu/update_menu
Traceback (most recent call last):
  File "/Users/xzr/Desktop/pipy/djmyframework/djmyframework/apps/myadmin/models/menu.py", line 250, in create_menu_from_config
    selfId, parentId, order = cls.getIdAndParentId(mc.von)  # 处理获得id，父id，排序
  File "/Users/xzr/Desktop/pipy/djmyframework/djmyframework/apps/myadmin/models/menu.py", line 290, in getIdAndParentId
    return selfId, int(parentId), order
TypeError: int() argument must be a string, a bytes-like object or a number, not 'NoneType'

During handling of the above exception, another exception occurred:

Traceback (most recent call last):
  File "/Users/xzr/.virtualenvs/djmyframework/lib/python3.7/site-packages/django/core/handlers/exception.py", line 34, in inner
    response = get_response(request)
  File "/Users/xzr/.virtualenvs/djmyframework/lib/python3.7/site-packages/django/core/handlers/base.py", line 115, in _get_response
    response = self.process_exception_by_middleware(e, request)
  File "/Users/xzr/.virtualenvs/djmyframework/lib/python3.7/site-packages/django/core/handlers/base.py", line 113, in _get_response
    response = wrapped_callback(request, *callback_args, **callback_kwargs)
  File "/Users/xzr/.virtualenvs/djmyframework/lib/python3.7/site-packages/django/views/decorators/csrf.py", line 54, in wrapped_view
    return view_func(*args, **kwargs)
  File "/Users/xzr/.virtualenvs/djmyframework/lib/python3.7/site-packages/rest_framework/viewsets.py", line 125, in view
    return self.dispatch(request, *args, **kwargs)
  File "/Users/xzr/.virtualenvs/djmyframework/lib/python3.7/site-packages/rest_framework/views.py", line 509, in dispatch
    response = self.handle_exception(exc)
  File "/Users/xzr/.virtualenvs/djmyframework/lib/python3.7/site-packages/rest_framework/views.py", line 469, in handle_exception
    self.raise_uncaught_exception(exc)
  File "/Users/xzr/.virtualenvs/djmyframework/lib/python3.7/site-packages/rest_framework/views.py", line 480, in raise_uncaught_exception
    raise exc
  File "/Users/xzr/.virtualenvs/djmyframework/lib/python3.7/site-packages/rest_framework/views.py", line 506, in dispatch
    response = handler(request, *args, **kwargs)
  File "/Users/xzr/Desktop/pipy/djmyframework/djmyframework/apps/myadmin/views/menu.py", line 110, in update_menu
    MenuConfig.create_menu_from_config(add_mc_list)
  File "/Users/xzr/Desktop/pipy/djmyframework/djmyframework/framework/utils/single_process.py", line 56, in wrapper
    return f(*args, **kwargs)
  File "/Users/xzr/Desktop/pipy/djmyframework/djmyframework/apps/myadmin/models/menu.py", line 275, in create_menu_from_config
    raise Exception
Exception
[2021-04-09T12:22:04+0800] [WARNING] [root] [pid:49335] [middleware.py:81] Traceback (most recent call last):
  File "/Users/xzr/Desktop/pipy/djmyframework/djmyframework/apps/myadmin/models/menu.py", line 250, in create_menu_from_config
    selfId, parentId, order = cls.getIdAndParentId(mc.von)  # 处理获得id，父id，排序
  File "/Users/xzr/Desktop/pipy/djmyframework/djmyframework/apps/myadmin/models/menu.py", line 290, in getIdAndParentId
    return selfId, int(parentId), order
TypeError: int() argument must be a string, a bytes-like object or a number, not 'NoneType'

During handling of the above exception, another exception occurred:

Traceback (most recent call last):
  File "/Users/xzr/.virtualenvs/djmyframework/lib/python3.7/site-packages/django/core/handlers/base.py", line 113, in _get_response
    response = wrapped_callback(request, *callback_args, **callback_kwargs)
  File "/Users/xzr/.virtualenvs/djmyframework/lib/python3.7/site-packages/django/views/decorators/csrf.py", line 54, in wrapped_view
    return view_func(*args, **kwargs)
  File "/Users/xzr/.virtualenvs/djmyframework/lib/python3.7/site-packages/rest_framework/viewsets.py", line 125, in view
    return self.dispatch(request, *args, **kwargs)
  File "/Users/xzr/.virtualenvs/djmyframework/lib/python3.7/site-packages/rest_framework/views.py", line 509, in dispatch
    response = self.handle_exception(exc)
  File "/Users/xzr/.virtualenvs/djmyframework/lib/python3.7/site-packages/rest_framework/views.py", line 469, in handle_exception
    self.raise_uncaught_exception(exc)
  File "/Users/xzr/.virtualenvs/djmyframework/lib/python3.7/site-packages/rest_framework/views.py", line 480, in raise_uncaught_exception
    raise exc
  File "/Users/xzr/.virtualenvs/djmyframework/lib/python3.7/site-packages/rest_framework/views.py", line 506, in dispatch
    response = handler(request, *args, **kwargs)
  File "/Users/xzr/Desktop/pipy/djmyframework/djmyframework/apps/myadmin/views/menu.py", line 110, in update_menu
    MenuConfig.create_menu_from_config(add_mc_list)
  File "/Users/xzr/Desktop/pipy/djmyframework/djmyframework/framework/utils/single_process.py", line 56, in wrapper
    return f(*args, **kwargs)
  File "/Users/xzr/Desktop/pipy/djmyframework/djmyframework/apps/myadmin/models/menu.py", line 275, in create_menu_from_config
    raise Exception
Exception

[2021-04-09T12:22:05+0800] [ERROR] [django.request] [pid:49335] [log.py:228] Internal Server Error: /myadmin/menu/update_menu
Traceback (most recent call last):
  File "/Users/xzr/Desktop/pipy/djmyframework/djmyframework/apps/myadmin/models/menu.py", line 250, in create_menu_from_config
    selfId, parentId, order = cls.getIdAndParentId(mc.von)  # 处理获得id，父id，排序
  File "/Users/xzr/Desktop/pipy/djmyframework/djmyframework/apps/myadmin/models/menu.py", line 290, in getIdAndParentId
    return selfId, int(parentId), order
TypeError: int() argument must be a string, a bytes-like object or a number, not 'NoneType'

During handling of the above exception, another exception occurred:

Traceback (most recent call last):
  File "/Users/xzr/.virtualenvs/djmyframework/lib/python3.7/site-packages/django/core/handlers/exception.py", line 34, in inner
    response = get_response(request)
  File "/Users/xzr/.virtualenvs/djmyframework/lib/python3.7/site-packages/django/core/handlers/base.py", line 115, in _get_response
    response = self.process_exception_by_middleware(e, request)
  File "/Users/xzr/.virtualenvs/djmyframework/lib/python3.7/site-packages/django/core/handlers/base.py", line 113, in _get_response
    response = wrapped_callback(request, *callback_args, **callback_kwargs)
  File "/Users/xzr/.virtualenvs/djmyframework/lib/python3.7/site-packages/django/views/decorators/csrf.py", line 54, in wrapped_view
    return view_func(*args, **kwargs)
  File "/Users/xzr/.virtualenvs/djmyframework/lib/python3.7/site-packages/rest_framework/viewsets.py", line 125, in view
    return self.dispatch(request, *args, **kwargs)
  File "/Users/xzr/.virtualenvs/djmyframework/lib/python3.7/site-packages/rest_framework/views.py", line 509, in dispatch
    response = self.handle_exception(exc)
  File "/Users/xzr/.virtualenvs/djmyframework/lib/python3.7/site-packages/rest_framework/views.py", line 469, in handle_exception
    self.raise_uncaught_exception(exc)
  File "/Users/xzr/.virtualenvs/djmyframework/lib/python3.7/site-packages/rest_framework/views.py", line 480, in raise_uncaught_exception
    raise exc
  File "/Users/xzr/.virtualenvs/djmyframework/lib/python3.7/site-packages/rest_framework/views.py", line 506, in dispatch
    response = handler(request, *args, **kwargs)
  File "/Users/xzr/Desktop/pipy/djmyframework/djmyframework/apps/myadmin/views/menu.py", line 110, in update_menu
    MenuConfig.create_menu_from_config(add_mc_list)
  File "/Users/xzr/Desktop/pipy/djmyframework/djmyframework/framework/utils/single_process.py", line 56, in wrapper
    return f(*args, **kwargs)
  File "/Users/xzr/Desktop/pipy/djmyframework/djmyframework/apps/myadmin/models/menu.py", line 275, in create_menu_from_config
    raise Exception
Exception
[2021-04-09T13:25:54+0800] [WARNING] [root] [pid:50053] [middleware.py:81] Traceback (most recent call last):
  File "/Users/xzr/.virtualenvs/djmyframework/lib/python3.7/site-packages/django/apps/registry.py", line 155, in get_app_config
    return self.app_configs[app_label]
KeyError: 'i18n'

During handling of the above exception, another exception occurred:

Traceback (most recent call last):
  File "/Users/xzr/.virtualenvs/djmyframework/lib/python3.7/site-packages/django/core/handlers/base.py", line 113, in _get_response
    response = wrapped_callback(request, *callback_args, **callback_kwargs)
  File "/Users/xzr/.virtualenvs/djmyframework/lib/python3.7/site-packages/django/views/decorators/csrf.py", line 54, in wrapped_view
    return view_func(*args, **kwargs)
  File "/Users/xzr/.virtualenvs/djmyframework/lib/python3.7/site-packages/rest_framework/viewsets.py", line 125, in view
    return self.dispatch(request, *args, **kwargs)
  File "/Users/xzr/.virtualenvs/djmyframework/lib/python3.7/site-packages/rest_framework/views.py", line 509, in dispatch
    response = self.handle_exception(exc)
  File "/Users/xzr/.virtualenvs/djmyframework/lib/python3.7/site-packages/rest_framework/views.py", line 469, in handle_exception
    self.raise_uncaught_exception(exc)
  File "/Users/xzr/.virtualenvs/djmyframework/lib/python3.7/site-packages/rest_framework/views.py", line 480, in raise_uncaught_exception
    raise exc
  File "/Users/xzr/.virtualenvs/djmyframework/lib/python3.7/site-packages/rest_framework/views.py", line 506, in dispatch
    response = handler(request, *args, **kwargs)
  File "/Users/xzr/Desktop/pipy/djmyframework/djmyframework/apps/myadmin/views/menu.py", line 96, in update_menu
    install_app_menu_config_list = MenuConfig.get_install_app_menu_config_list()
  File "/Users/xzr/Desktop/pipy/djmyframework/djmyframework/apps/myadmin/models/menu.py", line 190, in get_install_app_menu_config_list
    app_alias = apps.get_app_config(app_name).verbose_name or app_name
  File "/Users/xzr/.virtualenvs/djmyframework/lib/python3.7/site-packages/django/apps/registry.py", line 162, in get_app_config
    raise LookupError(message)
LookupError: No installed app with label 'i18n'.

[2021-04-09T13:25:54+0800] [ERROR] [django.request] [pid:50053] [log.py:228] Internal Server Error: /myadmin/menu/update_menu
[2021-04-09T13:27:43+0800] [WARNING] [root] [pid:50074] [middleware.py:81] Traceback (most recent call last):
  File "/Users/xzr/.virtualenvs/djmyframework/lib/python3.7/site-packages/django/apps/registry.py", line 155, in get_app_config
    return self.app_configs[app_label]
KeyError: 'i18n'

During handling of the above exception, another exception occurred:

Traceback (most recent call last):
  File "/Users/xzr/.virtualenvs/djmyframework/lib/python3.7/site-packages/django/core/handlers/base.py", line 113, in _get_response
    response = wrapped_callback(request, *callback_args, **callback_kwargs)
  File "/Users/xzr/.virtualenvs/djmyframework/lib/python3.7/site-packages/django/views/decorators/csrf.py", line 54, in wrapped_view
    return view_func(*args, **kwargs)
  File "/Users/xzr/.virtualenvs/djmyframework/lib/python3.7/site-packages/rest_framework/viewsets.py", line 125, in view
    return self.dispatch(request, *args, **kwargs)
  File "/Users/xzr/.virtualenvs/djmyframework/lib/python3.7/site-packages/rest_framework/views.py", line 509, in dispatch
    response = self.handle_exception(exc)
  File "/Users/xzr/.virtualenvs/djmyframework/lib/python3.7/site-packages/rest_framework/views.py", line 469, in handle_exception
    self.raise_uncaught_exception(exc)
  File "/Users/xzr/.virtualenvs/djmyframework/lib/python3.7/site-packages/rest_framework/views.py", line 480, in raise_uncaught_exception
    raise exc
  File "/Users/xzr/.virtualenvs/djmyframework/lib/python3.7/site-packages/rest_framework/views.py", line 506, in dispatch
    response = handler(request, *args, **kwargs)
  File "/Users/xzr/Desktop/pipy/djmyframework/djmyframework/apps/myadmin/views/menu.py", line 96, in update_menu
    install_app_menu_config_list = MenuConfig.get_install_app_menu_config_list()
  File "/Users/xzr/Desktop/pipy/djmyframework/djmyframework/apps/myadmin/models/menu.py", line 190, in get_install_app_menu_config_list
    app_alias = apps.get_app_config(app_name).verbose_name or app_name
  File "/Users/xzr/.virtualenvs/djmyframework/lib/python3.7/site-packages/django/apps/registry.py", line 162, in get_app_config
    raise LookupError(message)
LookupError: No installed app with label 'i18n'.

[2021-04-09T13:27:43+0800] [ERROR] [django.request] [pid:50074] [log.py:228] Internal Server Error: /myadmin/menu/update_menu
[2021-04-09T13:44:22+0800] [WARNING] [root] [pid:50346] [middleware.py:81] Traceback (most recent call last):
  File "/Users/xzr/.virtualenvs/djmyframework/lib/python3.7/site-packages/rest_framework/views.py", line 497, in dispatch
    self.initial(request, *args, **kwargs)
  File "/Users/xzr/Desktop/pipy/djmyframework/djmyframework/framework/views.py", line 355, in initial
    self.response = Response()
  File "/Users/xzr/Desktop/pipy/djmyframework/djmyframework/framework/response.py", line 59, in __init__
    self.context = RspData(data=data, code=code, msg=msg)
  File "/Users/xzr/Desktop/pipy/djmyframework/djmyframework/framework/response.py", line 44, in __init__
    self.data = ObjectDict(data)
  File "/Users/xzr/.virtualenvs/djmyframework/lib/python3.7/site-packages/objectdict.py", line 15, in __init__
    super(ObjectDict, self).__init__(*args, **kwargs)
TypeError: 'NoneType' object is not iterable

During handling of the above exception, another exception occurred:

Traceback (most recent call last):
  File "/Users/xzr/.virtualenvs/djmyframework/lib/python3.7/site-packages/rest_framework/request.py", line 416, in __getattr__
    return getattr(self._request, attr)
AttributeError: 'ASGIRequest' object has no attribute 'accepted_renderer'

During handling of the above exception, another exception occurred:

Traceback (most recent call last):
  File "/Users/xzr/.virtualenvs/djmyframework/lib/python3.7/site-packages/django/core/handlers/base.py", line 113, in _get_response
    response = wrapped_callback(request, *callback_args, **callback_kwargs)
  File "/Users/xzr/.virtualenvs/djmyframework/lib/python3.7/site-packages/django/views/decorators/csrf.py", line 54, in wrapped_view
    return view_func(*args, **kwargs)
  File "/Users/xzr/.virtualenvs/djmyframework/lib/python3.7/site-packages/rest_framework/viewsets.py", line 125, in view
    return self.dispatch(request, *args, **kwargs)
  File "/Users/xzr/.virtualenvs/djmyframework/lib/python3.7/site-packages/rest_framework/views.py", line 509, in dispatch
    response = self.handle_exception(exc)
  File "/Users/xzr/.virtualenvs/djmyframework/lib/python3.7/site-packages/rest_framework/views.py", line 469, in handle_exception
    self.raise_uncaught_exception(exc)
  File "/Users/xzr/.virtualenvs/djmyframework/lib/python3.7/site-packages/rest_framework/views.py", line 477, in raise_uncaught_exception
    renderer_format = getattr(request.accepted_renderer, 'format')
  File "/Users/xzr/.virtualenvs/djmyframework/lib/python3.7/site-packages/rest_framework/request.py", line 418, in __getattr__
    return self.__getattribute__(attr)
AttributeError: 'Request' object has no attribute 'accepted_renderer'

[2021-04-09T13:44:23+0800] [ERROR] [django.request] [pid:50346] [log.py:228] Internal Server Error: /myadmin/menu/update_menu
Traceback (most recent call last):
  File "/Users/xzr/.virtualenvs/djmyframework/lib/python3.7/site-packages/rest_framework/views.py", line 497, in dispatch
    self.initial(request, *args, **kwargs)
  File "/Users/xzr/Desktop/pipy/djmyframework/djmyframework/framework/views.py", line 355, in initial
    self.response = Response()
  File "/Users/xzr/Desktop/pipy/djmyframework/djmyframework/framework/response.py", line 59, in __init__
    self.context = RspData(data=data, code=code, msg=msg)
  File "/Users/xzr/Desktop/pipy/djmyframework/djmyframework/framework/response.py", line 44, in __init__
    self.data = ObjectDict(data)
  File "/Users/xzr/.virtualenvs/djmyframework/lib/python3.7/site-packages/objectdict.py", line 15, in __init__
    super(ObjectDict, self).__init__(*args, **kwargs)
TypeError: 'NoneType' object is not iterable

During handling of the above exception, another exception occurred:

Traceback (most recent call last):
  File "/Users/xzr/.virtualenvs/djmyframework/lib/python3.7/site-packages/rest_framework/request.py", line 416, in __getattr__
    return getattr(self._request, attr)
AttributeError: 'ASGIRequest' object has no attribute 'accepted_renderer'

During handling of the above exception, another exception occurred:

Traceback (most recent call last):
  File "/Users/xzr/.virtualenvs/djmyframework/lib/python3.7/site-packages/django/core/handlers/exception.py", line 34, in inner
    response = get_response(request)
  File "/Users/xzr/.virtualenvs/djmyframework/lib/python3.7/site-packages/django/core/handlers/base.py", line 115, in _get_response
    response = self.process_exception_by_middleware(e, request)
  File "/Users/xzr/.virtualenvs/djmyframework/lib/python3.7/site-packages/django/core/handlers/base.py", line 113, in _get_response
    response = wrapped_callback(request, *callback_args, **callback_kwargs)
  File "/Users/xzr/.virtualenvs/djmyframework/lib/python3.7/site-packages/django/views/decorators/csrf.py", line 54, in wrapped_view
    return view_func(*args, **kwargs)
  File "/Users/xzr/.virtualenvs/djmyframework/lib/python3.7/site-packages/rest_framework/viewsets.py", line 125, in view
    return self.dispatch(request, *args, **kwargs)
  File "/Users/xzr/.virtualenvs/djmyframework/lib/python3.7/site-packages/rest_framework/views.py", line 509, in dispatch
    response = self.handle_exception(exc)
  File "/Users/xzr/.virtualenvs/djmyframework/lib/python3.7/site-packages/rest_framework/views.py", line 469, in handle_exception
    self.raise_uncaught_exception(exc)
  File "/Users/xzr/.virtualenvs/djmyframework/lib/python3.7/site-packages/rest_framework/views.py", line 477, in raise_uncaught_exception
    renderer_format = getattr(request.accepted_renderer, 'format')
  File "/Users/xzr/.virtualenvs/djmyframework/lib/python3.7/site-packages/rest_framework/request.py", line 418, in __getattr__
    return self.__getattribute__(attr)
AttributeError: 'Request' object has no attribute 'accepted_renderer'
[2021-04-09T15:15:59+0800] [WARNING] [root] [pid:51752] [middleware.py:81] Traceback (most recent call last):
  File "/Users/xzr/Desktop/pipy/djmyframework/djmyframework/apps/myadmin/models/menu.py", line 252, in create_menu_from_config
    parentId, order = cls.get_mc_parent(mc)  # 处理获得id，父id，排序
  File "/Users/xzr/Desktop/pipy/djmyframework/djmyframework/apps/myadmin/models/menu.py", line 291, in get_mc_parent
    Menu.objects.filter(name=parent_name).first().only('id'))
AttributeError: 'Menu' object has no attribute 'only'

During handling of the above exception, another exception occurred:

Traceback (most recent call last):
  File "/Users/xzr/.virtualenvs/djmyframework/lib/python3.7/site-packages/django/core/handlers/base.py", line 113, in _get_response
    response = wrapped_callback(request, *callback_args, **callback_kwargs)
  File "/Users/xzr/.virtualenvs/djmyframework/lib/python3.7/site-packages/django/views/decorators/csrf.py", line 54, in wrapped_view
    return view_func(*args, **kwargs)
  File "/Users/xzr/.virtualenvs/djmyframework/lib/python3.7/site-packages/rest_framework/viewsets.py", line 125, in view
    return self.dispatch(request, *args, **kwargs)
  File "/Users/xzr/.virtualenvs/djmyframework/lib/python3.7/site-packages/rest_framework/views.py", line 509, in dispatch
    response = self.handle_exception(exc)
  File "/Users/xzr/.virtualenvs/djmyframework/lib/python3.7/site-packages/rest_framework/views.py", line 469, in handle_exception
    self.raise_uncaught_exception(exc)
  File "/Users/xzr/.virtualenvs/djmyframework/lib/python3.7/site-packages/rest_framework/views.py", line 480, in raise_uncaught_exception
    raise exc
  File "/Users/xzr/.virtualenvs/djmyframework/lib/python3.7/site-packages/rest_framework/views.py", line 506, in dispatch
    response = handler(request, *args, **kwargs)
  File "/Users/xzr/Desktop/pipy/djmyframework/djmyframework/apps/myadmin/views/menu.py", line 104, in update_menu
    MenuConfig.create_menu_from_config(install_app_menu_config_list, add_menus)
  File "/Users/xzr/Desktop/pipy/djmyframework/djmyframework/framework/utils/single_process.py", line 56, in wrapper
    return f(*args, **kwargs)
  File "/Users/xzr/Desktop/pipy/djmyframework/djmyframework/apps/myadmin/models/menu.py", line 275, in create_menu_from_config
    raise Exception
Exception

[2021-04-09T15:16:01+0800] [ERROR] [django.request] [pid:51752] [log.py:228] Internal Server Error: /myadmin/menu/update_menu
Traceback (most recent call last):
  File "/Users/xzr/Desktop/pipy/djmyframework/djmyframework/apps/myadmin/models/menu.py", line 252, in create_menu_from_config
    parentId, order = cls.get_mc_parent(mc)  # 处理获得id，父id，排序
  File "/Users/xzr/Desktop/pipy/djmyframework/djmyframework/apps/myadmin/models/menu.py", line 291, in get_mc_parent
    Menu.objects.filter(name=parent_name).first().only('id'))
AttributeError: 'Menu' object has no attribute 'only'

During handling of the above exception, another exception occurred:

Traceback (most recent call last):
  File "/Users/xzr/.virtualenvs/djmyframework/lib/python3.7/site-packages/django/core/handlers/exception.py", line 34, in inner
    response = get_response(request)
  File "/Users/xzr/.virtualenvs/djmyframework/lib/python3.7/site-packages/django/core/handlers/base.py", line 115, in _get_response
    response = self.process_exception_by_middleware(e, request)
  File "/Users/xzr/.virtualenvs/djmyframework/lib/python3.7/site-packages/django/core/handlers/base.py", line 113, in _get_response
    response = wrapped_callback(request, *callback_args, **callback_kwargs)
  File "/Users/xzr/.virtualenvs/djmyframework/lib/python3.7/site-packages/django/views/decorators/csrf.py", line 54, in wrapped_view
    return view_func(*args, **kwargs)
  File "/Users/xzr/.virtualenvs/djmyframework/lib/python3.7/site-packages/rest_framework/viewsets.py", line 125, in view
    return self.dispatch(request, *args, **kwargs)
  File "/Users/xzr/.virtualenvs/djmyframework/lib/python3.7/site-packages/rest_framework/views.py", line 509, in dispatch
    response = self.handle_exception(exc)
  File "/Users/xzr/.virtualenvs/djmyframework/lib/python3.7/site-packages/rest_framework/views.py", line 469, in handle_exception
    self.raise_uncaught_exception(exc)
  File "/Users/xzr/.virtualenvs/djmyframework/lib/python3.7/site-packages/rest_framework/views.py", line 480, in raise_uncaught_exception
    raise exc
  File "/Users/xzr/.virtualenvs/djmyframework/lib/python3.7/site-packages/rest_framework/views.py", line 506, in dispatch
    response = handler(request, *args, **kwargs)
  File "/Users/xzr/Desktop/pipy/djmyframework/djmyframework/apps/myadmin/views/menu.py", line 104, in update_menu
    MenuConfig.create_menu_from_config(install_app_menu_config_list, add_menus)
  File "/Users/xzr/Desktop/pipy/djmyframework/djmyframework/framework/utils/single_process.py", line 56, in wrapper
    return f(*args, **kwargs)
  File "/Users/xzr/Desktop/pipy/djmyframework/djmyframework/apps/myadmin/models/menu.py", line 275, in create_menu_from_config
    raise Exception
Exception
[2021-04-09T15:40:14+0800] [WARNING] [root] [pid:52186] [middleware.py:81] Traceback (most recent call last):
  File "/Users/xzr/.virtualenvs/djmyframework/lib/python3.7/site-packages/django/db/backends/utils.py", line 86, in _execute
    return self.cursor.execute(sql, params)
  File "/Users/xzr/.virtualenvs/djmyframework/lib/python3.7/site-packages/django/db/backends/mysql/base.py", line 74, in execute
    return self.cursor.execute(query, args)
  File "/Users/xzr/.virtualenvs/djmyframework/lib/python3.7/site-packages/pymysql/cursors.py", line 148, in execute
    result = self._query(query)
  File "/Users/xzr/.virtualenvs/djmyframework/lib/python3.7/site-packages/pymysql/cursors.py", line 310, in _query
    conn.query(q)
  File "/Users/xzr/.virtualenvs/djmyframework/lib/python3.7/site-packages/pymysql/connections.py", line 548, in query
    self._affected_rows = self._read_query_result(unbuffered=unbuffered)
  File "/Users/xzr/.virtualenvs/djmyframework/lib/python3.7/site-packages/pymysql/connections.py", line 775, in _read_query_result
    result.read()
  File "/Users/xzr/.virtualenvs/djmyframework/lib/python3.7/site-packages/pymysql/connections.py", line 1156, in read
    first_packet = self.connection._read_packet()
  File "/Users/xzr/.virtualenvs/djmyframework/lib/python3.7/site-packages/pymysql/connections.py", line 725, in _read_packet
    packet.raise_for_error()
  File "/Users/xzr/.virtualenvs/djmyframework/lib/python3.7/site-packages/pymysql/protocol.py", line 221, in raise_for_error
    err.raise_mysql_exception(self._data)
  File "/Users/xzr/.virtualenvs/djmyframework/lib/python3.7/site-packages/pymysql/err.py", line 143, in raise_mysql_exception
    raise errorclass(errno, errval)
pymysql.err.IntegrityError: (1048, "Column 'parent_id' cannot be null")

The above exception was the direct cause of the following exception:

Traceback (most recent call last):
  File "/Users/xzr/Desktop/pipy/djmyframework/djmyframework/apps/myadmin/models/menu.py", line 272, in create_menu_from_config
    menu_model.save()
  File "/Users/xzr/Desktop/pipy/djmyframework/djmyframework/apps/myadmin/models/menu.py", line 57, in save
    return super(Menu, self).save(*args, **kwargs)
  File "/Users/xzr/Desktop/pipy/djmyframework/djmyframework/framework/models.py", line 305, in save
    return super(BaseModel, self).save(*args, **kwargs)
  File "/Users/xzr/.virtualenvs/djmyframework/lib/python3.7/site-packages/django/db/models/base.py", line 749, in save
    force_update=force_update, update_fields=update_fields)
  File "/Users/xzr/.virtualenvs/djmyframework/lib/python3.7/site-packages/django/db/models/base.py", line 787, in save_base
    force_update, using, update_fields,
  File "/Users/xzr/.virtualenvs/djmyframework/lib/python3.7/site-packages/django/db/models/base.py", line 890, in _save_table
    results = self._do_insert(cls._base_manager, using, fields, returning_fields, raw)
  File "/Users/xzr/.virtualenvs/djmyframework/lib/python3.7/site-packages/django/db/models/base.py", line 929, in _do_insert
    using=using, raw=raw,
  File "/Users/xzr/.virtualenvs/djmyframework/lib/python3.7/site-packages/django/db/models/manager.py", line 82, in manager_method
    return getattr(self.get_queryset(), name)(*args, **kwargs)
  File "/Users/xzr/.virtualenvs/djmyframework/lib/python3.7/site-packages/django/db/models/query.py", line 1204, in _insert
    return query.get_compiler(using=using).execute_sql(returning_fields)
  File "/Users/xzr/.virtualenvs/djmyframework/lib/python3.7/site-packages/django/db/models/sql/compiler.py", line 1394, in execute_sql
    cursor.execute(sql, params)
  File "/Users/xzr/.virtualenvs/djmyframework/lib/python3.7/site-packages/django/db/backends/utils.py", line 100, in execute
    return super().execute(sql, params)
  File "/Users/xzr/.virtualenvs/djmyframework/lib/python3.7/site-packages/django/db/backends/utils.py", line 68, in execute
    return self._execute_with_wrappers(sql, params, many=False, executor=self._execute)
  File "/Users/xzr/.virtualenvs/djmyframework/lib/python3.7/site-packages/django/db/backends/utils.py", line 77, in _execute_with_wrappers
    return executor(sql, params, many, context)
  File "/Users/xzr/.virtualenvs/djmyframework/lib/python3.7/site-packages/django/db/backends/utils.py", line 86, in _execute
    return self.cursor.execute(sql, params)
  File "/Users/xzr/.virtualenvs/djmyframework/lib/python3.7/site-packages/django/db/utils.py", line 90, in __exit__
    raise dj_exc_value.with_traceback(traceback) from exc_value
  File "/Users/xzr/.virtualenvs/djmyframework/lib/python3.7/site-packages/django/db/backends/utils.py", line 86, in _execute
    return self.cursor.execute(sql, params)
  File "/Users/xzr/.virtualenvs/djmyframework/lib/python3.7/site-packages/django/db/backends/mysql/base.py", line 74, in execute
    return self.cursor.execute(query, args)
  File "/Users/xzr/.virtualenvs/djmyframework/lib/python3.7/site-packages/pymysql/cursors.py", line 148, in execute
    result = self._query(query)
  File "/Users/xzr/.virtualenvs/djmyframework/lib/python3.7/site-packages/pymysql/cursors.py", line 310, in _query
    conn.query(q)
  File "/Users/xzr/.virtualenvs/djmyframework/lib/python3.7/site-packages/pymysql/connections.py", line 548, in query
    self._affected_rows = self._read_query_result(unbuffered=unbuffered)
  File "/Users/xzr/.virtualenvs/djmyframework/lib/python3.7/site-packages/pymysql/connections.py", line 775, in _read_query_result
    result.read()
  File "/Users/xzr/.virtualenvs/djmyframework/lib/python3.7/site-packages/pymysql/connections.py", line 1156, in read
    first_packet = self.connection._read_packet()
  File "/Users/xzr/.virtualenvs/djmyframework/lib/python3.7/site-packages/pymysql/connections.py", line 725, in _read_packet
    packet.raise_for_error()
  File "/Users/xzr/.virtualenvs/djmyframework/lib/python3.7/site-packages/pymysql/protocol.py", line 221, in raise_for_error
    err.raise_mysql_exception(self._data)
  File "/Users/xzr/.virtualenvs/djmyframework/lib/python3.7/site-packages/pymysql/err.py", line 143, in raise_mysql_exception
    raise errorclass(errno, errval)
django.db.utils.IntegrityError: (1048, "Column 'parent_id' cannot be null")

During handling of the above exception, another exception occurred:

Traceback (most recent call last):
  File "/Users/xzr/.virtualenvs/djmyframework/lib/python3.7/site-packages/django/core/handlers/base.py", line 113, in _get_response
    response = wrapped_callback(request, *callback_args, **callback_kwargs)
  File "/Users/xzr/.virtualenvs/djmyframework/lib/python3.7/site-packages/django/views/decorators/csrf.py", line 54, in wrapped_view
    return view_func(*args, **kwargs)
  File "/Users/xzr/.virtualenvs/djmyframework/lib/python3.7/site-packages/rest_framework/viewsets.py", line 125, in view
    return self.dispatch(request, *args, **kwargs)
  File "/Users/xzr/.virtualenvs/djmyframework/lib/python3.7/site-packages/rest_framework/views.py", line 509, in dispatch
    response = self.handle_exception(exc)
  File "/Users/xzr/.virtualenvs/djmyframework/lib/python3.7/site-packages/rest_framework/views.py", line 469, in handle_exception
    self.raise_uncaught_exception(exc)
  File "/Users/xzr/.virtualenvs/djmyframework/lib/python3.7/site-packages/rest_framework/views.py", line 480, in raise_uncaught_exception
    raise exc
  File "/Users/xzr/.virtualenvs/djmyframework/lib/python3.7/site-packages/rest_framework/views.py", line 506, in dispatch
    response = handler(request, *args, **kwargs)
  File "/Users/xzr/Desktop/pipy/djmyframework/djmyframework/apps/myadmin/views/menu.py", line 104, in update_menu
    MenuConfig.create_menu_from_config(install_app_menu_config_list, add_menus=add_menus)
  File "/Users/xzr/Desktop/pipy/djmyframework/djmyframework/framework/utils/single_process.py", line 56, in wrapper
    return f(*args, **kwargs)
  File "/Users/xzr/Desktop/pipy/djmyframework/djmyframework/apps/myadmin/models/menu.py", line 279, in create_menu_from_config
    raise Exception
Exception

[2021-04-09T15:40:15+0800] [ERROR] [django.request] [pid:52186] [log.py:228] Internal Server Error: /myadmin/menu/update_menu
Traceback (most recent call last):
  File "/Users/xzr/.virtualenvs/djmyframework/lib/python3.7/site-packages/django/db/backends/utils.py", line 86, in _execute
    return self.cursor.execute(sql, params)
  File "/Users/xzr/.virtualenvs/djmyframework/lib/python3.7/site-packages/django/db/backends/mysql/base.py", line 74, in execute
    return self.cursor.execute(query, args)
  File "/Users/xzr/.virtualenvs/djmyframework/lib/python3.7/site-packages/pymysql/cursors.py", line 148, in execute
    result = self._query(query)
  File "/Users/xzr/.virtualenvs/djmyframework/lib/python3.7/site-packages/pymysql/cursors.py", line 310, in _query
    conn.query(q)
  File "/Users/xzr/.virtualenvs/djmyframework/lib/python3.7/site-packages/pymysql/connections.py", line 548, in query
    self._affected_rows = self._read_query_result(unbuffered=unbuffered)
  File "/Users/xzr/.virtualenvs/djmyframework/lib/python3.7/site-packages/pymysql/connections.py", line 775, in _read_query_result
    result.read()
  File "/Users/xzr/.virtualenvs/djmyframework/lib/python3.7/site-packages/pymysql/connections.py", line 1156, in read
    first_packet = self.connection._read_packet()
  File "/Users/xzr/.virtualenvs/djmyframework/lib/python3.7/site-packages/pymysql/connections.py", line 725, in _read_packet
    packet.raise_for_error()
  File "/Users/xzr/.virtualenvs/djmyframework/lib/python3.7/site-packages/pymysql/protocol.py", line 221, in raise_for_error
    err.raise_mysql_exception(self._data)
  File "/Users/xzr/.virtualenvs/djmyframework/lib/python3.7/site-packages/pymysql/err.py", line 143, in raise_mysql_exception
    raise errorclass(errno, errval)
pymysql.err.IntegrityError: (1048, "Column 'parent_id' cannot be null")

The above exception was the direct cause of the following exception:

Traceback (most recent call last):
  File "/Users/xzr/Desktop/pipy/djmyframework/djmyframework/apps/myadmin/models/menu.py", line 272, in create_menu_from_config
    menu_model.save()
  File "/Users/xzr/Desktop/pipy/djmyframework/djmyframework/apps/myadmin/models/menu.py", line 57, in save
    return super(Menu, self).save(*args, **kwargs)
  File "/Users/xzr/Desktop/pipy/djmyframework/djmyframework/framework/models.py", line 305, in save
    return super(BaseModel, self).save(*args, **kwargs)
  File "/Users/xzr/.virtualenvs/djmyframework/lib/python3.7/site-packages/django/db/models/base.py", line 749, in save
    force_update=force_update, update_fields=update_fields)
  File "/Users/xzr/.virtualenvs/djmyframework/lib/python3.7/site-packages/django/db/models/base.py", line 787, in save_base
    force_update, using, update_fields,
  File "/Users/xzr/.virtualenvs/djmyframework/lib/python3.7/site-packages/django/db/models/base.py", line 890, in _save_table
    results = self._do_insert(cls._base_manager, using, fields, returning_fields, raw)
  File "/Users/xzr/.virtualenvs/djmyframework/lib/python3.7/site-packages/django/db/models/base.py", line 929, in _do_insert
    using=using, raw=raw,
  File "/Users/xzr/.virtualenvs/djmyframework/lib/python3.7/site-packages/django/db/models/manager.py", line 82, in manager_method
    return getattr(self.get_queryset(), name)(*args, **kwargs)
  File "/Users/xzr/.virtualenvs/djmyframework/lib/python3.7/site-packages/django/db/models/query.py", line 1204, in _insert
    return query.get_compiler(using=using).execute_sql(returning_fields)
  File "/Users/xzr/.virtualenvs/djmyframework/lib/python3.7/site-packages/django/db/models/sql/compiler.py", line 1394, in execute_sql
    cursor.execute(sql, params)
  File "/Users/xzr/.virtualenvs/djmyframework/lib/python3.7/site-packages/django/db/backends/utils.py", line 100, in execute
    return super().execute(sql, params)
  File "/Users/xzr/.virtualenvs/djmyframework/lib/python3.7/site-packages/django/db/backends/utils.py", line 68, in execute
    return self._execute_with_wrappers(sql, params, many=False, executor=self._execute)
  File "/Users/xzr/.virtualenvs/djmyframework/lib/python3.7/site-packages/django/db/backends/utils.py", line 77, in _execute_with_wrappers
    return executor(sql, params, many, context)
  File "/Users/xzr/.virtualenvs/djmyframework/lib/python3.7/site-packages/django/db/backends/utils.py", line 86, in _execute
    return self.cursor.execute(sql, params)
  File "/Users/xzr/.virtualenvs/djmyframework/lib/python3.7/site-packages/django/db/utils.py", line 90, in __exit__
    raise dj_exc_value.with_traceback(traceback) from exc_value
  File "/Users/xzr/.virtualenvs/djmyframework/lib/python3.7/site-packages/django/db/backends/utils.py", line 86, in _execute
    return self.cursor.execute(sql, params)
  File "/Users/xzr/.virtualenvs/djmyframework/lib/python3.7/site-packages/django/db/backends/mysql/base.py", line 74, in execute
    return self.cursor.execute(query, args)
  File "/Users/xzr/.virtualenvs/djmyframework/lib/python3.7/site-packages/pymysql/cursors.py", line 148, in execute
    result = self._query(query)
  File "/Users/xzr/.virtualenvs/djmyframework/lib/python3.7/site-packages/pymysql/cursors.py", line 310, in _query
    conn.query(q)
  File "/Users/xzr/.virtualenvs/djmyframework/lib/python3.7/site-packages/pymysql/connections.py", line 548, in query
    self._affected_rows = self._read_query_result(unbuffered=unbuffered)
  File "/Users/xzr/.virtualenvs/djmyframework/lib/python3.7/site-packages/pymysql/connections.py", line 775, in _read_query_result
    result.read()
  File "/Users/xzr/.virtualenvs/djmyframework/lib/python3.7/site-packages/pymysql/connections.py", line 1156, in read
    first_packet = self.connection._read_packet()
  File "/Users/xzr/.virtualenvs/djmyframework/lib/python3.7/site-packages/pymysql/connections.py", line 725, in _read_packet
    packet.raise_for_error()
  File "/Users/xzr/.virtualenvs/djmyframework/lib/python3.7/site-packages/pymysql/protocol.py", line 221, in raise_for_error
    err.raise_mysql_exception(self._data)
  File "/Users/xzr/.virtualenvs/djmyframework/lib/python3.7/site-packages/pymysql/err.py", line 143, in raise_mysql_exception
    raise errorclass(errno, errval)
django.db.utils.IntegrityError: (1048, "Column 'parent_id' cannot be null")

During handling of the above exception, another exception occurred:

Traceback (most recent call last):
  File "/Users/xzr/.virtualenvs/djmyframework/lib/python3.7/site-packages/django/core/handlers/exception.py", line 34, in inner
    response = get_response(request)
  File "/Users/xzr/.virtualenvs/djmyframework/lib/python3.7/site-packages/django/core/handlers/base.py", line 115, in _get_response
    response = self.process_exception_by_middleware(e, request)
  File "/Users/xzr/.virtualenvs/djmyframework/lib/python3.7/site-packages/django/core/handlers/base.py", line 113, in _get_response
    response = wrapped_callback(request, *callback_args, **callback_kwargs)
  File "/Users/xzr/.virtualenvs/djmyframework/lib/python3.7/site-packages/django/views/decorators/csrf.py", line 54, in wrapped_view
    return view_func(*args, **kwargs)
  File "/Users/xzr/.virtualenvs/djmyframework/lib/python3.7/site-packages/rest_framework/viewsets.py", line 125, in view
    return self.dispatch(request, *args, **kwargs)
  File "/Users/xzr/.virtualenvs/djmyframework/lib/python3.7/site-packages/rest_framework/views.py", line 509, in dispatch
    response = self.handle_exception(exc)
  File "/Users/xzr/.virtualenvs/djmyframework/lib/python3.7/site-packages/rest_framework/views.py", line 469, in handle_exception
    self.raise_uncaught_exception(exc)
  File "/Users/xzr/.virtualenvs/djmyframework/lib/python3.7/site-packages/rest_framework/views.py", line 480, in raise_uncaught_exception
    raise exc
  File "/Users/xzr/.virtualenvs/djmyframework/lib/python3.7/site-packages/rest_framework/views.py", line 506, in dispatch
    response = handler(request, *args, **kwargs)
  File "/Users/xzr/Desktop/pipy/djmyframework/djmyframework/apps/myadmin/views/menu.py", line 104, in update_menu
    MenuConfig.create_menu_from_config(install_app_menu_config_list, add_menus=add_menus)
  File "/Users/xzr/Desktop/pipy/djmyframework/djmyframework/framework/utils/single_process.py", line 56, in wrapper
    return f(*args, **kwargs)
  File "/Users/xzr/Desktop/pipy/djmyframework/djmyframework/apps/myadmin/models/menu.py", line 279, in create_menu_from_config
    raise Exception
Exception
[2021-04-09T15:41:35+0800] [WARNING] [root] [pid:52186] [middleware.py:81] Traceback (most recent call last):
  File "/Users/xzr/.virtualenvs/djmyframework/lib/python3.7/site-packages/django/db/backends/utils.py", line 86, in _execute
    return self.cursor.execute(sql, params)
  File "/Users/xzr/.virtualenvs/djmyframework/lib/python3.7/site-packages/django/db/backends/mysql/base.py", line 74, in execute
    return self.cursor.execute(query, args)
  File "/Users/xzr/.virtualenvs/djmyframework/lib/python3.7/site-packages/pymysql/cursors.py", line 148, in execute
    result = self._query(query)
  File "/Users/xzr/.virtualenvs/djmyframework/lib/python3.7/site-packages/pymysql/cursors.py", line 310, in _query
    conn.query(q)
  File "/Users/xzr/.virtualenvs/djmyframework/lib/python3.7/site-packages/pymysql/connections.py", line 548, in query
    self._affected_rows = self._read_query_result(unbuffered=unbuffered)
  File "/Users/xzr/.virtualenvs/djmyframework/lib/python3.7/site-packages/pymysql/connections.py", line 775, in _read_query_result
    result.read()
  File "/Users/xzr/.virtualenvs/djmyframework/lib/python3.7/site-packages/pymysql/connections.py", line 1156, in read
    first_packet = self.connection._read_packet()
  File "/Users/xzr/.virtualenvs/djmyframework/lib/python3.7/site-packages/pymysql/connections.py", line 725, in _read_packet
    packet.raise_for_error()
  File "/Users/xzr/.virtualenvs/djmyframework/lib/python3.7/site-packages/pymysql/protocol.py", line 221, in raise_for_error
    err.raise_mysql_exception(self._data)
  File "/Users/xzr/.virtualenvs/djmyframework/lib/python3.7/site-packages/pymysql/err.py", line 143, in raise_mysql_exception
    raise errorclass(errno, errval)
pymysql.err.IntegrityError: (1048, "Column 'parent_id' cannot be null")

The above exception was the direct cause of the following exception:

Traceback (most recent call last):
  File "/Users/xzr/Desktop/pipy/djmyframework/djmyframework/apps/myadmin/models/menu.py", line 272, in create_menu_from_config
    menu_model.save()
  File "/Users/xzr/Desktop/pipy/djmyframework/djmyframework/apps/myadmin/models/menu.py", line 57, in save
    return super(Menu, self).save(*args, **kwargs)
  File "/Users/xzr/Desktop/pipy/djmyframework/djmyframework/framework/models.py", line 305, in save
    return super(BaseModel, self).save(*args, **kwargs)
  File "/Users/xzr/.virtualenvs/djmyframework/lib/python3.7/site-packages/django/db/models/base.py", line 749, in save
    force_update=force_update, update_fields=update_fields)
  File "/Users/xzr/.virtualenvs/djmyframework/lib/python3.7/site-packages/django/db/models/base.py", line 787, in save_base
    force_update, using, update_fields,
  File "/Users/xzr/.virtualenvs/djmyframework/lib/python3.7/site-packages/django/db/models/base.py", line 890, in _save_table
    results = self._do_insert(cls._base_manager, using, fields, returning_fields, raw)
  File "/Users/xzr/.virtualenvs/djmyframework/lib/python3.7/site-packages/django/db/models/base.py", line 929, in _do_insert
    using=using, raw=raw,
  File "/Users/xzr/.virtualenvs/djmyframework/lib/python3.7/site-packages/django/db/models/manager.py", line 82, in manager_method
    return getattr(self.get_queryset(), name)(*args, **kwargs)
  File "/Users/xzr/.virtualenvs/djmyframework/lib/python3.7/site-packages/django/db/models/query.py", line 1204, in _insert
    return query.get_compiler(using=using).execute_sql(returning_fields)
  File "/Users/xzr/.virtualenvs/djmyframework/lib/python3.7/site-packages/django/db/models/sql/compiler.py", line 1394, in execute_sql
    cursor.execute(sql, params)
  File "/Users/xzr/.virtualenvs/djmyframework/lib/python3.7/site-packages/django/db/backends/utils.py", line 100, in execute
    return super().execute(sql, params)
  File "/Users/xzr/.virtualenvs/djmyframework/lib/python3.7/site-packages/django/db/backends/utils.py", line 68, in execute
    return self._execute_with_wrappers(sql, params, many=False, executor=self._execute)
  File "/Users/xzr/.virtualenvs/djmyframework/lib/python3.7/site-packages/django/db/backends/utils.py", line 77, in _execute_with_wrappers
    return executor(sql, params, many, context)
  File "/Users/xzr/.virtualenvs/djmyframework/lib/python3.7/site-packages/django/db/backends/utils.py", line 86, in _execute
    return self.cursor.execute(sql, params)
  File "/Users/xzr/.virtualenvs/djmyframework/lib/python3.7/site-packages/django/db/utils.py", line 90, in __exit__
    raise dj_exc_value.with_traceback(traceback) from exc_value
  File "/Users/xzr/.virtualenvs/djmyframework/lib/python3.7/site-packages/django/db/backends/utils.py", line 86, in _execute
    return self.cursor.execute(sql, params)
  File "/Users/xzr/.virtualenvs/djmyframework/lib/python3.7/site-packages/django/db/backends/mysql/base.py", line 74, in execute
    return self.cursor.execute(query, args)
  File "/Users/xzr/.virtualenvs/djmyframework/lib/python3.7/site-packages/pymysql/cursors.py", line 148, in execute
    result = self._query(query)
  File "/Users/xzr/.virtualenvs/djmyframework/lib/python3.7/site-packages/pymysql/cursors.py", line 310, in _query
    conn.query(q)
  File "/Users/xzr/.virtualenvs/djmyframework/lib/python3.7/site-packages/pymysql/connections.py", line 548, in query
    self._affected_rows = self._read_query_result(unbuffered=unbuffered)
  File "/Users/xzr/.virtualenvs/djmyframework/lib/python3.7/site-packages/pymysql/connections.py", line 775, in _read_query_result
    result.read()
  File "/Users/xzr/.virtualenvs/djmyframework/lib/python3.7/site-packages/pymysql/connections.py", line 1156, in read
    first_packet = self.connection._read_packet()
  File "/Users/xzr/.virtualenvs/djmyframework/lib/python3.7/site-packages/pymysql/connections.py", line 725, in _read_packet
    packet.raise_for_error()
  File "/Users/xzr/.virtualenvs/djmyframework/lib/python3.7/site-packages/pymysql/protocol.py", line 221, in raise_for_error
    err.raise_mysql_exception(self._data)
  File "/Users/xzr/.virtualenvs/djmyframework/lib/python3.7/site-packages/pymysql/err.py", line 143, in raise_mysql_exception
    raise errorclass(errno, errval)
django.db.utils.IntegrityError: (1048, "Column 'parent_id' cannot be null")

During handling of the above exception, another exception occurred:

Traceback (most recent call last):
  File "/Users/xzr/.virtualenvs/djmyframework/lib/python3.7/site-packages/django/core/handlers/base.py", line 113, in _get_response
    response = wrapped_callback(request, *callback_args, **callback_kwargs)
  File "/Users/xzr/.virtualenvs/djmyframework/lib/python3.7/site-packages/django/views/decorators/csrf.py", line 54, in wrapped_view
    return view_func(*args, **kwargs)
  File "/Users/xzr/.virtualenvs/djmyframework/lib/python3.7/site-packages/rest_framework/viewsets.py", line 125, in view
    return self.dispatch(request, *args, **kwargs)
  File "/Users/xzr/.virtualenvs/djmyframework/lib/python3.7/site-packages/rest_framework/views.py", line 509, in dispatch
    response = self.handle_exception(exc)
  File "/Users/xzr/.virtualenvs/djmyframework/lib/python3.7/site-packages/rest_framework/views.py", line 469, in handle_exception
    self.raise_uncaught_exception(exc)
  File "/Users/xzr/.virtualenvs/djmyframework/lib/python3.7/site-packages/rest_framework/views.py", line 480, in raise_uncaught_exception
    raise exc
  File "/Users/xzr/.virtualenvs/djmyframework/lib/python3.7/site-packages/rest_framework/views.py", line 506, in dispatch
    response = handler(request, *args, **kwargs)
  File "/Users/xzr/Desktop/pipy/djmyframework/djmyframework/apps/myadmin/views/menu.py", line 104, in update_menu
    MenuConfig.create_menu_from_config(install_app_menu_config_list, add_menus=add_menus)
  File "/Users/xzr/Desktop/pipy/djmyframework/djmyframework/framework/utils/single_process.py", line 56, in wrapper
    return f(*args, **kwargs)
  File "/Users/xzr/Desktop/pipy/djmyframework/djmyframework/apps/myadmin/models/menu.py", line 279, in create_menu_from_config
    raise Exception
Exception

[2021-04-09T15:41:40+0800] [ERROR] [django.request] [pid:52186] [log.py:228] Internal Server Error: /myadmin/menu/update_menu
Traceback (most recent call last):
  File "/Users/xzr/.virtualenvs/djmyframework/lib/python3.7/site-packages/django/db/backends/utils.py", line 86, in _execute
    return self.cursor.execute(sql, params)
  File "/Users/xzr/.virtualenvs/djmyframework/lib/python3.7/site-packages/django/db/backends/mysql/base.py", line 74, in execute
    return self.cursor.execute(query, args)
  File "/Users/xzr/.virtualenvs/djmyframework/lib/python3.7/site-packages/pymysql/cursors.py", line 148, in execute
    result = self._query(query)
  File "/Users/xzr/.virtualenvs/djmyframework/lib/python3.7/site-packages/pymysql/cursors.py", line 310, in _query
    conn.query(q)
  File "/Users/xzr/.virtualenvs/djmyframework/lib/python3.7/site-packages/pymysql/connections.py", line 548, in query
    self._affected_rows = self._read_query_result(unbuffered=unbuffered)
  File "/Users/xzr/.virtualenvs/djmyframework/lib/python3.7/site-packages/pymysql/connections.py", line 775, in _read_query_result
    result.read()
  File "/Users/xzr/.virtualenvs/djmyframework/lib/python3.7/site-packages/pymysql/connections.py", line 1156, in read
    first_packet = self.connection._read_packet()
  File "/Users/xzr/.virtualenvs/djmyframework/lib/python3.7/site-packages/pymysql/connections.py", line 725, in _read_packet
    packet.raise_for_error()
  File "/Users/xzr/.virtualenvs/djmyframework/lib/python3.7/site-packages/pymysql/protocol.py", line 221, in raise_for_error
    err.raise_mysql_exception(self._data)
  File "/Users/xzr/.virtualenvs/djmyframework/lib/python3.7/site-packages/pymysql/err.py", line 143, in raise_mysql_exception
    raise errorclass(errno, errval)
pymysql.err.IntegrityError: (1048, "Column 'parent_id' cannot be null")

The above exception was the direct cause of the following exception:

Traceback (most recent call last):
  File "/Users/xzr/Desktop/pipy/djmyframework/djmyframework/apps/myadmin/models/menu.py", line 272, in create_menu_from_config
    menu_model.save()
  File "/Users/xzr/Desktop/pipy/djmyframework/djmyframework/apps/myadmin/models/menu.py", line 57, in save
    return super(Menu, self).save(*args, **kwargs)
  File "/Users/xzr/Desktop/pipy/djmyframework/djmyframework/framework/models.py", line 305, in save
    return super(BaseModel, self).save(*args, **kwargs)
  File "/Users/xzr/.virtualenvs/djmyframework/lib/python3.7/site-packages/django/db/models/base.py", line 749, in save
    force_update=force_update, update_fields=update_fields)
  File "/Users/xzr/.virtualenvs/djmyframework/lib/python3.7/site-packages/django/db/models/base.py", line 787, in save_base
    force_update, using, update_fields,
  File "/Users/xzr/.virtualenvs/djmyframework/lib/python3.7/site-packages/django/db/models/base.py", line 890, in _save_table
    results = self._do_insert(cls._base_manager, using, fields, returning_fields, raw)
  File "/Users/xzr/.virtualenvs/djmyframework/lib/python3.7/site-packages/django/db/models/base.py", line 929, in _do_insert
    using=using, raw=raw,
  File "/Users/xzr/.virtualenvs/djmyframework/lib/python3.7/site-packages/django/db/models/manager.py", line 82, in manager_method
    return getattr(self.get_queryset(), name)(*args, **kwargs)
  File "/Users/xzr/.virtualenvs/djmyframework/lib/python3.7/site-packages/django/db/models/query.py", line 1204, in _insert
    return query.get_compiler(using=using).execute_sql(returning_fields)
  File "/Users/xzr/.virtualenvs/djmyframework/lib/python3.7/site-packages/django/db/models/sql/compiler.py", line 1394, in execute_sql
    cursor.execute(sql, params)
  File "/Users/xzr/.virtualenvs/djmyframework/lib/python3.7/site-packages/django/db/backends/utils.py", line 100, in execute
    return super().execute(sql, params)
  File "/Users/xzr/.virtualenvs/djmyframework/lib/python3.7/site-packages/django/db/backends/utils.py", line 68, in execute
    return self._execute_with_wrappers(sql, params, many=False, executor=self._execute)
  File "/Users/xzr/.virtualenvs/djmyframework/lib/python3.7/site-packages/django/db/backends/utils.py", line 77, in _execute_with_wrappers
    return executor(sql, params, many, context)
  File "/Users/xzr/.virtualenvs/djmyframework/lib/python3.7/site-packages/django/db/backends/utils.py", line 86, in _execute
    return self.cursor.execute(sql, params)
  File "/Users/xzr/.virtualenvs/djmyframework/lib/python3.7/site-packages/django/db/utils.py", line 90, in __exit__
    raise dj_exc_value.with_traceback(traceback) from exc_value
  File "/Users/xzr/.virtualenvs/djmyframework/lib/python3.7/site-packages/django/db/backends/utils.py", line 86, in _execute
    return self.cursor.execute(sql, params)
  File "/Users/xzr/.virtualenvs/djmyframework/lib/python3.7/site-packages/django/db/backends/mysql/base.py", line 74, in execute
    return self.cursor.execute(query, args)
  File "/Users/xzr/.virtualenvs/djmyframework/lib/python3.7/site-packages/pymysql/cursors.py", line 148, in execute
    result = self._query(query)
  File "/Users/xzr/.virtualenvs/djmyframework/lib/python3.7/site-packages/pymysql/cursors.py", line 310, in _query
    conn.query(q)
  File "/Users/xzr/.virtualenvs/djmyframework/lib/python3.7/site-packages/pymysql/connections.py", line 548, in query
    self._affected_rows = self._read_query_result(unbuffered=unbuffered)
  File "/Users/xzr/.virtualenvs/djmyframework/lib/python3.7/site-packages/pymysql/connections.py", line 775, in _read_query_result
    result.read()
  File "/Users/xzr/.virtualenvs/djmyframework/lib/python3.7/site-packages/pymysql/connections.py", line 1156, in read
    first_packet = self.connection._read_packet()
  File "/Users/xzr/.virtualenvs/djmyframework/lib/python3.7/site-packages/pymysql/connections.py", line 725, in _read_packet
    packet.raise_for_error()
  File "/Users/xzr/.virtualenvs/djmyframework/lib/python3.7/site-packages/pymysql/protocol.py", line 221, in raise_for_error
    err.raise_mysql_exception(self._data)
  File "/Users/xzr/.virtualenvs/djmyframework/lib/python3.7/site-packages/pymysql/err.py", line 143, in raise_mysql_exception
    raise errorclass(errno, errval)
django.db.utils.IntegrityError: (1048, "Column 'parent_id' cannot be null")

During handling of the above exception, another exception occurred:

Traceback (most recent call last):
  File "/Users/xzr/.virtualenvs/djmyframework/lib/python3.7/site-packages/django/core/handlers/exception.py", line 34, in inner
    response = get_response(request)
  File "/Users/xzr/.virtualenvs/djmyframework/lib/python3.7/site-packages/django/core/handlers/base.py", line 115, in _get_response
    response = self.process_exception_by_middleware(e, request)
  File "/Users/xzr/.virtualenvs/djmyframework/lib/python3.7/site-packages/django/core/handlers/base.py", line 113, in _get_response
    response = wrapped_callback(request, *callback_args, **callback_kwargs)
  File "/Users/xzr/.virtualenvs/djmyframework/lib/python3.7/site-packages/django/views/decorators/csrf.py", line 54, in wrapped_view
    return view_func(*args, **kwargs)
  File "/Users/xzr/.virtualenvs/djmyframework/lib/python3.7/site-packages/rest_framework/viewsets.py", line 125, in view
    return self.dispatch(request, *args, **kwargs)
  File "/Users/xzr/.virtualenvs/djmyframework/lib/python3.7/site-packages/rest_framework/views.py", line 509, in dispatch
    response = self.handle_exception(exc)
  File "/Users/xzr/.virtualenvs/djmyframework/lib/python3.7/site-packages/rest_framework/views.py", line 469, in handle_exception
    self.raise_uncaught_exception(exc)
  File "/Users/xzr/.virtualenvs/djmyframework/lib/python3.7/site-packages/rest_framework/views.py", line 480, in raise_uncaught_exception
    raise exc
  File "/Users/xzr/.virtualenvs/djmyframework/lib/python3.7/site-packages/rest_framework/views.py", line 506, in dispatch
    response = handler(request, *args, **kwargs)
  File "/Users/xzr/Desktop/pipy/djmyframework/djmyframework/apps/myadmin/views/menu.py", line 104, in update_menu
    MenuConfig.create_menu_from_config(install_app_menu_config_list, add_menus=add_menus)
  File "/Users/xzr/Desktop/pipy/djmyframework/djmyframework/framework/utils/single_process.py", line 56, in wrapper
    return f(*args, **kwargs)
  File "/Users/xzr/Desktop/pipy/djmyframework/djmyframework/apps/myadmin/models/menu.py", line 279, in create_menu_from_config
    raise Exception
Exception
[2021-04-09T16:48:16+0800] [WARNING] [root] [pid:53311] [middleware.py:81] Traceback (most recent call last):
  File "/Users/xzr/.virtualenvs/djmyframework/lib/python3.7/site-packages/django/core/handlers/base.py", line 113, in _get_response
    response = wrapped_callback(request, *callback_args, **callback_kwargs)
  File "/Users/xzr/.virtualenvs/djmyframework/lib/python3.7/site-packages/django/views/decorators/csrf.py", line 54, in wrapped_view
    return view_func(*args, **kwargs)
  File "/Users/xzr/.virtualenvs/djmyframework/lib/python3.7/site-packages/rest_framework/viewsets.py", line 125, in view
    return self.dispatch(request, *args, **kwargs)
  File "/Users/xzr/.virtualenvs/djmyframework/lib/python3.7/site-packages/rest_framework/views.py", line 509, in dispatch
    response = self.handle_exception(exc)
  File "/Users/xzr/.virtualenvs/djmyframework/lib/python3.7/site-packages/rest_framework/views.py", line 469, in handle_exception
    self.raise_uncaught_exception(exc)
  File "/Users/xzr/.virtualenvs/djmyframework/lib/python3.7/site-packages/rest_framework/views.py", line 480, in raise_uncaught_exception
    raise exc
  File "/Users/xzr/.virtualenvs/djmyframework/lib/python3.7/site-packages/rest_framework/views.py", line 506, in dispatch
    response = handler(request, *args, **kwargs)
  File "/Users/xzr/Desktop/pipy/djmyframework/djmyframework/apps/svn_admin/views.py", line 93, in preview_db_files
    auth_db_content = open(SVN_GROUP_DB_FILE).read() + open(SVN_AUTH_DB_FILE).read()
FileNotFoundError: [Errno 2] No such file or directory: '/Users/xzr/Desktop/svn/groups.ini'

[2021-04-09T16:48:16+0800] [ERROR] [django.request] [pid:53311] [log.py:228] Internal Server Error: /svn_admin/svn_path/preview_db_files
Traceback (most recent call last):
  File "/Users/xzr/.virtualenvs/djmyframework/lib/python3.7/site-packages/django/core/handlers/exception.py", line 34, in inner
    response = get_response(request)
  File "/Users/xzr/.virtualenvs/djmyframework/lib/python3.7/site-packages/django/core/handlers/base.py", line 115, in _get_response
    response = self.process_exception_by_middleware(e, request)
  File "/Users/xzr/.virtualenvs/djmyframework/lib/python3.7/site-packages/django/core/handlers/base.py", line 113, in _get_response
    response = wrapped_callback(request, *callback_args, **callback_kwargs)
  File "/Users/xzr/.virtualenvs/djmyframework/lib/python3.7/site-packages/django/views/decorators/csrf.py", line 54, in wrapped_view
    return view_func(*args, **kwargs)
  File "/Users/xzr/.virtualenvs/djmyframework/lib/python3.7/site-packages/rest_framework/viewsets.py", line 125, in view
    return self.dispatch(request, *args, **kwargs)
  File "/Users/xzr/.virtualenvs/djmyframework/lib/python3.7/site-packages/rest_framework/views.py", line 509, in dispatch
    response = self.handle_exception(exc)
  File "/Users/xzr/.virtualenvs/djmyframework/lib/python3.7/site-packages/rest_framework/views.py", line 469, in handle_exception
    self.raise_uncaught_exception(exc)
  File "/Users/xzr/.virtualenvs/djmyframework/lib/python3.7/site-packages/rest_framework/views.py", line 480, in raise_uncaught_exception
    raise exc
  File "/Users/xzr/.virtualenvs/djmyframework/lib/python3.7/site-packages/rest_framework/views.py", line 506, in dispatch
    response = handler(request, *args, **kwargs)
  File "/Users/xzr/Desktop/pipy/djmyframework/djmyframework/apps/svn_admin/views.py", line 93, in preview_db_files
    auth_db_content = open(SVN_GROUP_DB_FILE).read() + open(SVN_AUTH_DB_FILE).read()
FileNotFoundError: [Errno 2] No such file or directory: '/Users/xzr/Desktop/svn/groups.ini'
[2021-04-09T16:48:19+0800] [WARNING] [root] [pid:53311] [middleware.py:81] Traceback (most recent call last):
  File "/Users/xzr/.virtualenvs/djmyframework/lib/python3.7/site-packages/django/core/handlers/base.py", line 113, in _get_response
    response = wrapped_callback(request, *callback_args, **callback_kwargs)
  File "/Users/xzr/.virtualenvs/djmyframework/lib/python3.7/site-packages/django/views/decorators/csrf.py", line 54, in wrapped_view
    return view_func(*args, **kwargs)
  File "/Users/xzr/.virtualenvs/djmyframework/lib/python3.7/site-packages/rest_framework/viewsets.py", line 125, in view
    return self.dispatch(request, *args, **kwargs)
  File "/Users/xzr/.virtualenvs/djmyframework/lib/python3.7/site-packages/rest_framework/views.py", line 509, in dispatch
    response = self.handle_exception(exc)
  File "/Users/xzr/.virtualenvs/djmyframework/lib/python3.7/site-packages/rest_framework/views.py", line 469, in handle_exception
    self.raise_uncaught_exception(exc)
  File "/Users/xzr/.virtualenvs/djmyframework/lib/python3.7/site-packages/rest_framework/views.py", line 480, in raise_uncaught_exception
    raise exc
  File "/Users/xzr/.virtualenvs/djmyframework/lib/python3.7/site-packages/rest_framework/views.py", line 506, in dispatch
    response = handler(request, *args, **kwargs)
  File "/Users/xzr/Desktop/pipy/djmyframework/djmyframework/apps/svn_admin/views.py", line 93, in preview_db_files
    auth_db_content = open(SVN_GROUP_DB_FILE).read() + open(SVN_AUTH_DB_FILE).read()
FileNotFoundError: [Errno 2] No such file or directory: '/Users/xzr/Desktop/svn/groups.ini'

[2021-04-09T16:48:19+0800] [ERROR] [django.request] [pid:53311] [log.py:228] Internal Server Error: /svn_admin/svn_path/preview_db_files
Traceback (most recent call last):
  File "/Users/xzr/.virtualenvs/djmyframework/lib/python3.7/site-packages/django/core/handlers/exception.py", line 34, in inner
    response = get_response(request)
  File "/Users/xzr/.virtualenvs/djmyframework/lib/python3.7/site-packages/django/core/handlers/base.py", line 115, in _get_response
    response = self.process_exception_by_middleware(e, request)
  File "/Users/xzr/.virtualenvs/djmyframework/lib/python3.7/site-packages/django/core/handlers/base.py", line 113, in _get_response
    response = wrapped_callback(request, *callback_args, **callback_kwargs)
  File "/Users/xzr/.virtualenvs/djmyframework/lib/python3.7/site-packages/django/views/decorators/csrf.py", line 54, in wrapped_view
    return view_func(*args, **kwargs)
  File "/Users/xzr/.virtualenvs/djmyframework/lib/python3.7/site-packages/rest_framework/viewsets.py", line 125, in view
    return self.dispatch(request, *args, **kwargs)
  File "/Users/xzr/.virtualenvs/djmyframework/lib/python3.7/site-packages/rest_framework/views.py", line 509, in dispatch
    response = self.handle_exception(exc)
  File "/Users/xzr/.virtualenvs/djmyframework/lib/python3.7/site-packages/rest_framework/views.py", line 469, in handle_exception
    self.raise_uncaught_exception(exc)
  File "/Users/xzr/.virtualenvs/djmyframework/lib/python3.7/site-packages/rest_framework/views.py", line 480, in raise_uncaught_exception
    raise exc
  File "/Users/xzr/.virtualenvs/djmyframework/lib/python3.7/site-packages/rest_framework/views.py", line 506, in dispatch
    response = handler(request, *args, **kwargs)
  File "/Users/xzr/Desktop/pipy/djmyframework/djmyframework/apps/svn_admin/views.py", line 93, in preview_db_files
    auth_db_content = open(SVN_GROUP_DB_FILE).read() + open(SVN_AUTH_DB_FILE).read()
FileNotFoundError: [Errno 2] No such file or directory: '/Users/xzr/Desktop/svn/groups.ini'
[2021-04-09T17:46:12+0800] [WARNING] [root] [pid:54342] [middleware.py:81] Traceback (most recent call last):
  File "/Users/xzr/.virtualenvs/djmyframework/lib/python3.7/site-packages/django/core/handlers/base.py", line 113, in _get_response
    response = wrapped_callback(request, *callback_args, **callback_kwargs)
  File "/Users/xzr/.virtualenvs/djmyframework/lib/python3.7/site-packages/django/views/decorators/csrf.py", line 54, in wrapped_view
    return view_func(*args, **kwargs)
  File "/Users/xzr/.virtualenvs/djmyframework/lib/python3.7/site-packages/rest_framework/viewsets.py", line 125, in view
    return self.dispatch(request, *args, **kwargs)
  File "/Users/xzr/.virtualenvs/djmyframework/lib/python3.7/site-packages/rest_framework/views.py", line 509, in dispatch
    response = self.handle_exception(exc)
  File "/Users/xzr/.virtualenvs/djmyframework/lib/python3.7/site-packages/rest_framework/views.py", line 469, in handle_exception
    self.raise_uncaught_exception(exc)
  File "/Users/xzr/.virtualenvs/djmyframework/lib/python3.7/site-packages/rest_framework/views.py", line 480, in raise_uncaught_exception
    raise exc
  File "/Users/xzr/.virtualenvs/djmyframework/lib/python3.7/site-packages/rest_framework/views.py", line 506, in dispatch
    response = handler(request, *args, **kwargs)
  File "/Users/xzr/Desktop/pipy/djmyframework/djmyframework/apps/svn_admin/views.py", line 93, in preview_db_files
    auth_db_content = open(SVN_GROUP_DB_FILE).read() + open(SVN_AUTH_DB_FILE).read()
FileNotFoundError: [Errno 2] No such file or directory: '/Users/xzr/Desktop/svn/conf/groups.ini'

[2021-04-09T17:46:12+0800] [ERROR] [django.request] [pid:54342] [log.py:228] Internal Server Error: /svn_admin/svn_path/preview_db_files
Traceback (most recent call last):
  File "/Users/xzr/.virtualenvs/djmyframework/lib/python3.7/site-packages/django/core/handlers/exception.py", line 34, in inner
    response = get_response(request)
  File "/Users/xzr/.virtualenvs/djmyframework/lib/python3.7/site-packages/django/core/handlers/base.py", line 115, in _get_response
    response = self.process_exception_by_middleware(e, request)
  File "/Users/xzr/.virtualenvs/djmyframework/lib/python3.7/site-packages/django/core/handlers/base.py", line 113, in _get_response
    response = wrapped_callback(request, *callback_args, **callback_kwargs)
  File "/Users/xzr/.virtualenvs/djmyframework/lib/python3.7/site-packages/django/views/decorators/csrf.py", line 54, in wrapped_view
    return view_func(*args, **kwargs)
  File "/Users/xzr/.virtualenvs/djmyframework/lib/python3.7/site-packages/rest_framework/viewsets.py", line 125, in view
    return self.dispatch(request, *args, **kwargs)
  File "/Users/xzr/.virtualenvs/djmyframework/lib/python3.7/site-packages/rest_framework/views.py", line 509, in dispatch
    response = self.handle_exception(exc)
  File "/Users/xzr/.virtualenvs/djmyframework/lib/python3.7/site-packages/rest_framework/views.py", line 469, in handle_exception
    self.raise_uncaught_exception(exc)
  File "/Users/xzr/.virtualenvs/djmyframework/lib/python3.7/site-packages/rest_framework/views.py", line 480, in raise_uncaught_exception
    raise exc
  File "/Users/xzr/.virtualenvs/djmyframework/lib/python3.7/site-packages/rest_framework/views.py", line 506, in dispatch
    response = handler(request, *args, **kwargs)
  File "/Users/xzr/Desktop/pipy/djmyframework/djmyframework/apps/svn_admin/views.py", line 93, in preview_db_files
    auth_db_content = open(SVN_GROUP_DB_FILE).read() + open(SVN_AUTH_DB_FILE).read()
FileNotFoundError: [Errno 2] No such file or directory: '/Users/xzr/Desktop/svn/conf/groups.ini'
[2021-04-09T17:46:28+0800] [WARNING] [root] [pid:54342] [middleware.py:81] Traceback (most recent call last):
  File "/Users/xzr/.virtualenvs/djmyframework/lib/python3.7/site-packages/django/core/handlers/base.py", line 113, in _get_response
    response = wrapped_callback(request, *callback_args, **callback_kwargs)
  File "/Users/xzr/.virtualenvs/djmyframework/lib/python3.7/site-packages/django/views/decorators/csrf.py", line 54, in wrapped_view
    return view_func(*args, **kwargs)
  File "/Users/xzr/.virtualenvs/djmyframework/lib/python3.7/site-packages/rest_framework/viewsets.py", line 125, in view
    return self.dispatch(request, *args, **kwargs)
  File "/Users/xzr/.virtualenvs/djmyframework/lib/python3.7/site-packages/rest_framework/views.py", line 509, in dispatch
    response = self.handle_exception(exc)
  File "/Users/xzr/.virtualenvs/djmyframework/lib/python3.7/site-packages/rest_framework/views.py", line 469, in handle_exception
    self.raise_uncaught_exception(exc)
  File "/Users/xzr/.virtualenvs/djmyframework/lib/python3.7/site-packages/rest_framework/views.py", line 480, in raise_uncaught_exception
    raise exc
  File "/Users/xzr/.virtualenvs/djmyframework/lib/python3.7/site-packages/rest_framework/views.py", line 506, in dispatch
    response = handler(request, *args, **kwargs)
  File "/Users/xzr/Desktop/pipy/djmyframework/djmyframework/apps/svn_admin/views.py", line 75, in save
    return super(SvnPathSet, self).save(request)
  File "/Users/xzr/Desktop/pipy/djmyframework/djmyframework/framework/views.py", line 468, in save
    serializer, msg = self.save_instance(request)
  File "/Users/xzr/Desktop/pipy/djmyframework/djmyframework/framework/views.py", line 457, in save_instance
    serializer.save(**kwargs)
  File "/Users/xzr/Desktop/pipy/djmyframework/djmyframework/framework/serializer.py", line 224, in save
    super(BaseModelSerializer, self).save(**kwargs)
  File "/Users/xzr/.virtualenvs/djmyframework/lib/python3.7/site-packages/rest_framework/serializers.py", line 200, in save
    self.instance = self.update(self.instance, validated_data)
  File "/Users/xzr/.virtualenvs/djmyframework/lib/python3.7/site-packages/rest_framework/serializers.py", line 983, in update
    instance.save()
  File "/Users/xzr/Desktop/pipy/djmyframework/djmyframework/apps/svn_admin/models.py", line 61, in save
    SvnPath.sync_svn_config_file()
  File "/Users/xzr/Desktop/pipy/djmyframework/djmyframework/apps/svn_admin/models.py", line 132, in sync_svn_config_file
    cls.sync_user_to_password_db()
  File "/Users/xzr/Desktop/pipy/djmyframework/djmyframework/apps/svn_admin/models.py", line 171, in sync_user_to_password_db
    password_db.set(user_section_name, user.username, svnuser.password)
AttributeError: 'SvnUser' object has no attribute 'password'

[2021-04-09T17:46:28+0800] [ERROR] [django.request] [pid:54342] [log.py:228] Internal Server Error: /svn_admin/svn_path/save
[2021-04-09T17:54:23+0800] [WARNING] [root] [pid:54439] [middleware.py:81] Traceback (most recent call last):
  File "/Users/xzr/.virtualenvs/djmyframework/lib/python3.7/site-packages/django/template/backends/jinja2.py", line 39, in get_template
    return Template(self.env.get_template(template_name), self)
  File "/Users/xzr/.virtualenvs/djmyframework/lib/python3.7/site-packages/jinja2/environment.py", line 883, in get_template
    return self._load_template(name, self.make_globals(globals))
  File "/Users/xzr/.virtualenvs/djmyframework/lib/python3.7/site-packages/jinja2/environment.py", line 857, in _load_template
    template = self.loader.load(self, name, globals)
  File "/Users/xzr/.virtualenvs/djmyframework/lib/python3.7/site-packages/jinja2/loaders.py", line 127, in load
    code = environment.compile(source, name, filename)
  File "/Users/xzr/.virtualenvs/djmyframework/lib/python3.7/site-packages/jinja2/environment.py", line 638, in compile
    self.handle_exception(source=source_hint)
  File "/Users/xzr/.virtualenvs/djmyframework/lib/python3.7/site-packages/jinja2/environment.py", line 832, in handle_exception
    reraise(*rewrite_traceback_stack(source=source))
  File "/Users/xzr/.virtualenvs/djmyframework/lib/python3.7/site-packages/jinja2/_compat.py", line 28, in reraise
    raise value.with_traceback(tb)
  File "/Users/xzr/Desktop/pipy/djmyframework/djmyframework/apps/svn_admin/jinja2_templates/svn_admin/svn_path/list.html", line 441, in template
    art.dialog.prompt('{{ _('请输入仓库代号,只能英文字符'}}', function (val) {
jinja2.exceptions.TemplateSyntaxError: unexpected '}', expected ')'

The above exception was the direct cause of the following exception:

Traceback (most recent call last):
  File "/Users/xzr/.virtualenvs/djmyframework/lib/python3.7/site-packages/django/core/handlers/base.py", line 143, in _get_response
    response = response.render()
  File "/Users/xzr/.virtualenvs/djmyframework/lib/python3.7/site-packages/django/template/response.py", line 105, in render
    self.content = self.rendered_content
  File "/Users/xzr/Desktop/pipy/djmyframework/djmyframework/framework/response.py", line 107, in rendered_content
    return super(Response, self).rendered_content
  File "/Users/xzr/.virtualenvs/djmyframework/lib/python3.7/site-packages/rest_framework/response.py", line 70, in rendered_content
    ret = renderer.render(self.data, accepted_media_type, context)
  File "/Users/xzr/.virtualenvs/djmyframework/lib/python3.7/site-packages/rest_framework/renderers.py", line 160, in render
    template = self.resolve_template(template_names)
  File "/Users/xzr/.virtualenvs/djmyframework/lib/python3.7/site-packages/rest_framework/renderers.py", line 170, in resolve_template
    return loader.select_template(template_names)
  File "/Users/xzr/.virtualenvs/djmyframework/lib/python3.7/site-packages/django/template/loader.py", line 42, in select_template
    return engine.get_template(template_name)
  File "/Users/xzr/.virtualenvs/djmyframework/lib/python3.7/site-packages/django/template/backends/jinja2.py", line 45, in get_template
    raise new from exc
django.template.exceptions.TemplateSyntaxError: ("unexpected '}', expected ')'",)

[2021-04-09T17:54:23+0800] [ERROR] [django.request] [pid:54439] [log.py:228] Internal Server Error: /svn_admin/svn_path/list
Traceback (most recent call last):
  File "/Users/xzr/.virtualenvs/djmyframework/lib/python3.7/site-packages/django/template/backends/jinja2.py", line 39, in get_template
    return Template(self.env.get_template(template_name), self)
  File "/Users/xzr/.virtualenvs/djmyframework/lib/python3.7/site-packages/jinja2/environment.py", line 883, in get_template
    return self._load_template(name, self.make_globals(globals))
  File "/Users/xzr/.virtualenvs/djmyframework/lib/python3.7/site-packages/jinja2/environment.py", line 857, in _load_template
    template = self.loader.load(self, name, globals)
  File "/Users/xzr/.virtualenvs/djmyframework/lib/python3.7/site-packages/jinja2/loaders.py", line 127, in load
    code = environment.compile(source, name, filename)
  File "/Users/xzr/.virtualenvs/djmyframework/lib/python3.7/site-packages/jinja2/environment.py", line 638, in compile
    self.handle_exception(source=source_hint)
  File "/Users/xzr/.virtualenvs/djmyframework/lib/python3.7/site-packages/jinja2/environment.py", line 832, in handle_exception
    reraise(*rewrite_traceback_stack(source=source))
  File "/Users/xzr/.virtualenvs/djmyframework/lib/python3.7/site-packages/jinja2/_compat.py", line 28, in reraise
    raise value.with_traceback(tb)
  File "/Users/xzr/Desktop/pipy/djmyframework/djmyframework/apps/svn_admin/jinja2_templates/svn_admin/svn_path/list.html", line 441, in template
    art.dialog.prompt('{{ _('请输入仓库代号,只能英文字符'}}', function (val) {
jinja2.exceptions.TemplateSyntaxError: unexpected '}', expected ')'

The above exception was the direct cause of the following exception:

Traceback (most recent call last):
  File "/Users/xzr/.virtualenvs/djmyframework/lib/python3.7/site-packages/django/core/handlers/exception.py", line 34, in inner
    response = get_response(request)
  File "/Users/xzr/.virtualenvs/djmyframework/lib/python3.7/site-packages/django/core/handlers/base.py", line 145, in _get_response
    response = self.process_exception_by_middleware(e, request)
  File "/Users/xzr/.virtualenvs/djmyframework/lib/python3.7/site-packages/django/core/handlers/base.py", line 143, in _get_response
    response = response.render()
  File "/Users/xzr/.virtualenvs/djmyframework/lib/python3.7/site-packages/django/template/response.py", line 105, in render
    self.content = self.rendered_content
  File "/Users/xzr/Desktop/pipy/djmyframework/djmyframework/framework/response.py", line 107, in rendered_content
    return super(Response, self).rendered_content
  File "/Users/xzr/.virtualenvs/djmyframework/lib/python3.7/site-packages/rest_framework/response.py", line 70, in rendered_content
    ret = renderer.render(self.data, accepted_media_type, context)
  File "/Users/xzr/.virtualenvs/djmyframework/lib/python3.7/site-packages/rest_framework/renderers.py", line 160, in render
    template = self.resolve_template(template_names)
  File "/Users/xzr/.virtualenvs/djmyframework/lib/python3.7/site-packages/rest_framework/renderers.py", line 170, in resolve_template
    return loader.select_template(template_names)
  File "/Users/xzr/.virtualenvs/djmyframework/lib/python3.7/site-packages/django/template/loader.py", line 42, in select_template
    return engine.get_template(template_name)
  File "/Users/xzr/.virtualenvs/djmyframework/lib/python3.7/site-packages/django/template/backends/jinja2.py", line 45, in get_template
    raise new from exc
django.template.exceptions.TemplateSyntaxError: ("unexpected '}', expected ')'",)
[2021-04-09T17:56:19+0800] [WARNING] [root] [pid:54527] [middleware.py:81] Traceback (most recent call last):
  File "/Users/xzr/.virtualenvs/djmyframework/lib/python3.7/site-packages/django/core/handlers/base.py", line 113, in _get_response
    response = wrapped_callback(request, *callback_args, **callback_kwargs)
  File "/Users/xzr/.virtualenvs/djmyframework/lib/python3.7/site-packages/django/views/decorators/csrf.py", line 54, in wrapped_view
    return view_func(*args, **kwargs)
  File "/Users/xzr/.virtualenvs/djmyframework/lib/python3.7/site-packages/rest_framework/viewsets.py", line 125, in view
    return self.dispatch(request, *args, **kwargs)
  File "/Users/xzr/.virtualenvs/djmyframework/lib/python3.7/site-packages/rest_framework/views.py", line 509, in dispatch
    response = self.handle_exception(exc)
  File "/Users/xzr/.virtualenvs/djmyframework/lib/python3.7/site-packages/rest_framework/views.py", line 469, in handle_exception
    self.raise_uncaught_exception(exc)
  File "/Users/xzr/.virtualenvs/djmyframework/lib/python3.7/site-packages/rest_framework/views.py", line 480, in raise_uncaught_exception
    raise exc
  File "/Users/xzr/.virtualenvs/djmyframework/lib/python3.7/site-packages/rest_framework/views.py", line 506, in dispatch
    response = handler(request, *args, **kwargs)
  File "/Users/xzr/Desktop/pipy/djmyframework/djmyframework/apps/svn_admin/views.py", line 102, in create_svnrepo
    SvnPath.create_svnrepo(svnrepo_name)
  File "/Users/xzr/Desktop/pipy/djmyframework/djmyframework/apps/svn_admin/models.py", line 100, in create_svnrepo
    os.removedirs(svnrepo_conf_path)
  File "/Library/Frameworks/Python.framework/Versions/3.7/lib/python3.7/os.py", line 239, in removedirs
    rmdir(name)
OSError: [Errno 66] Directory not empty: '/Users/xzr/Desktop/svn/asd/conf'

[2021-04-09T17:56:19+0800] [ERROR] [django.request] [pid:54527] [log.py:228] Internal Server Error: /svn_admin/svn_path/create_svnrepo
[2021-04-09T17:56:20+0800] [WARNING] [root] [pid:54527] [middleware.py:81] Traceback (most recent call last):
  File "/Users/xzr/.virtualenvs/djmyframework/lib/python3.7/site-packages/asgiref/sync.py", line 208, in main_wrap
    raise exc_info[1]
  File "/Users/xzr/.virtualenvs/djmyframework/lib/python3.7/site-packages/django/db/models/query.py", line 559, in get_or_create
    return self.get(**kwargs), False
  File "/Users/xzr/.virtualenvs/djmyframework/lib/python3.7/site-packages/django/db/models/query.py", line 417, in get
    self.model._meta.object_name
svn_admin.models.SvnPath.DoesNotExist: SvnPath matching query does not exist.

During handling of the above exception, another exception occurred:

Traceback (most recent call last):
  File "/Users/xzr/.virtualenvs/djmyframework/lib/python3.7/site-packages/django/core/handlers/base.py", line 113, in _get_response
    response = wrapped_callback(request, *callback_args, **callback_kwargs)
  File "/Users/xzr/.virtualenvs/djmyframework/lib/python3.7/site-packages/django/views/decorators/csrf.py", line 54, in wrapped_view
    return view_func(*args, **kwargs)
  File "/Users/xzr/.virtualenvs/djmyframework/lib/python3.7/site-packages/rest_framework/viewsets.py", line 125, in view
    return self.dispatch(request, *args, **kwargs)
  File "/Users/xzr/.virtualenvs/djmyframework/lib/python3.7/site-packages/rest_framework/views.py", line 509, in dispatch
    response = self.handle_exception(exc)
  File "/Users/xzr/.virtualenvs/djmyframework/lib/python3.7/site-packages/rest_framework/views.py", line 469, in handle_exception
    self.raise_uncaught_exception(exc)
  File "/Users/xzr/.virtualenvs/djmyframework/lib/python3.7/site-packages/rest_framework/views.py", line 480, in raise_uncaught_exception
    raise exc
  File "/Users/xzr/.virtualenvs/djmyframework/lib/python3.7/site-packages/rest_framework/views.py", line 506, in dispatch
    response = handler(request, *args, **kwargs)
  File "/Users/xzr/Desktop/pipy/djmyframework/djmyframework/apps/svn_admin/views.py", line 63, in list
    SvnPath.init_svn_projects()
  File "/Users/xzr/Desktop/pipy/djmyframework/djmyframework/apps/svn_admin/models.py", line 156, in init_svn_projects
    svn_paht_model = cls.objects.get_or_create(project_name=project_name, parent=None, path='/')
  File "/Users/xzr/.virtualenvs/djmyframework/lib/python3.7/site-packages/django/db/models/manager.py", line 82, in manager_method
    return getattr(self.get_queryset(), name)(*args, **kwargs)
  File "/Users/xzr/.virtualenvs/djmyframework/lib/python3.7/site-packages/django/db/models/query.py", line 562, in get_or_create
    return self._create_object_from_params(kwargs, params)
  File "/Users/xzr/.virtualenvs/djmyframework/lib/python3.7/site-packages/django/db/models/query.py", line 596, in _create_object_from_params
    obj = self.create(**params)
  File "/Users/xzr/.virtualenvs/djmyframework/lib/python3.7/site-packages/django/db/models/query.py", line 433, in create
    obj.save(force_insert=True, using=self.db)
  File "/Users/xzr/Desktop/pipy/djmyframework/djmyframework/apps/svn_admin/models.py", line 61, in save
    SvnPath.sync_svn_config_file()
  File "/Users/xzr/Desktop/pipy/djmyframework/djmyframework/apps/svn_admin/models.py", line 132, in sync_svn_config_file
    cls.sync_user_to_password_db()
  File "/Users/xzr/Desktop/pipy/djmyframework/djmyframework/apps/svn_admin/models.py", line 171, in sync_user_to_password_db
    password_db.set(user_section_name, user.username, svnuser.password)
AttributeError: 'SvnUser' object has no attribute 'password'

[2021-04-09T17:56:20+0800] [ERROR] [django.request] [pid:54527] [log.py:228] Internal Server Error: /svn_admin/svn_path/list
Traceback (most recent call last):
  File "/Users/xzr/.virtualenvs/djmyframework/lib/python3.7/site-packages/asgiref/sync.py", line 208, in main_wrap
    raise exc_info[1]
  File "/Users/xzr/.virtualenvs/djmyframework/lib/python3.7/site-packages/django/db/models/query.py", line 559, in get_or_create
    return self.get(**kwargs), False
  File "/Users/xzr/.virtualenvs/djmyframework/lib/python3.7/site-packages/django/db/models/query.py", line 417, in get
    self.model._meta.object_name
svn_admin.models.SvnPath.DoesNotExist: SvnPath matching query does not exist.

During handling of the above exception, another exception occurred:

Traceback (most recent call last):
  File "/Users/xzr/.virtualenvs/djmyframework/lib/python3.7/site-packages/django/core/handlers/exception.py", line 34, in inner
    response = get_response(request)
  File "/Users/xzr/.virtualenvs/djmyframework/lib/python3.7/site-packages/django/core/handlers/base.py", line 115, in _get_response
    response = self.process_exception_by_middleware(e, request)
  File "/Users/xzr/.virtualenvs/djmyframework/lib/python3.7/site-packages/django/core/handlers/base.py", line 113, in _get_response
    response = wrapped_callback(request, *callback_args, **callback_kwargs)
  File "/Users/xzr/.virtualenvs/djmyframework/lib/python3.7/site-packages/django/views/decorators/csrf.py", line 54, in wrapped_view
    return view_func(*args, **kwargs)
  File "/Users/xzr/.virtualenvs/djmyframework/lib/python3.7/site-packages/rest_framework/viewsets.py", line 125, in view
    return self.dispatch(request, *args, **kwargs)
  File "/Users/xzr/.virtualenvs/djmyframework/lib/python3.7/site-packages/rest_framework/views.py", line 509, in dispatch
    response = self.handle_exception(exc)
  File "/Users/xzr/.virtualenvs/djmyframework/lib/python3.7/site-packages/rest_framework/views.py", line 469, in handle_exception
    self.raise_uncaught_exception(exc)
  File "/Users/xzr/.virtualenvs/djmyframework/lib/python3.7/site-packages/rest_framework/views.py", line 480, in raise_uncaught_exception
    raise exc
  File "/Users/xzr/.virtualenvs/djmyframework/lib/python3.7/site-packages/rest_framework/views.py", line 506, in dispatch
    response = handler(request, *args, **kwargs)
  File "/Users/xzr/Desktop/pipy/djmyframework/djmyframework/apps/svn_admin/views.py", line 63, in list
    SvnPath.init_svn_projects()
  File "/Users/xzr/Desktop/pipy/djmyframework/djmyframework/apps/svn_admin/models.py", line 156, in init_svn_projects
    svn_paht_model = cls.objects.get_or_create(project_name=project_name, parent=None, path='/')
  File "/Users/xzr/.virtualenvs/djmyframework/lib/python3.7/site-packages/django/db/models/manager.py", line 82, in manager_method
    return getattr(self.get_queryset(), name)(*args, **kwargs)
  File "/Users/xzr/.virtualenvs/djmyframework/lib/python3.7/site-packages/django/db/models/query.py", line 562, in get_or_create
    return self._create_object_from_params(kwargs, params)
  File "/Users/xzr/.virtualenvs/djmyframework/lib/python3.7/site-packages/django/db/models/query.py", line 596, in _create_object_from_params
    obj = self.create(**params)
  File "/Users/xzr/.virtualenvs/djmyframework/lib/python3.7/site-packages/django/db/models/query.py", line 433, in create
    obj.save(force_insert=True, using=self.db)
  File "/Users/xzr/Desktop/pipy/djmyframework/djmyframework/apps/svn_admin/models.py", line 61, in save
    SvnPath.sync_svn_config_file()
  File "/Users/xzr/Desktop/pipy/djmyframework/djmyframework/apps/svn_admin/models.py", line 132, in sync_svn_config_file
    cls.sync_user_to_password_db()
  File "/Users/xzr/Desktop/pipy/djmyframework/djmyframework/apps/svn_admin/models.py", line 171, in sync_user_to_password_db
    password_db.set(user_section_name, user.username, svnuser.password)
AttributeError: 'SvnUser' object has no attribute 'password'
[2021-04-09T17:56:31+0800] [WARNING] [root] [pid:54527] [middleware.py:81] Traceback (most recent call last):
  File "/Users/xzr/.virtualenvs/djmyframework/lib/python3.7/site-packages/django/core/handlers/base.py", line 113, in _get_response
    response = wrapped_callback(request, *callback_args, **callback_kwargs)
  File "/Users/xzr/.virtualenvs/djmyframework/lib/python3.7/site-packages/django/views/decorators/csrf.py", line 54, in wrapped_view
    return view_func(*args, **kwargs)
  File "/Users/xzr/.virtualenvs/djmyframework/lib/python3.7/site-packages/rest_framework/viewsets.py", line 125, in view
    return self.dispatch(request, *args, **kwargs)
  File "/Users/xzr/.virtualenvs/djmyframework/lib/python3.7/site-packages/rest_framework/views.py", line 509, in dispatch
    response = self.handle_exception(exc)
  File "/Users/xzr/.virtualenvs/djmyframework/lib/python3.7/site-packages/rest_framework/views.py", line 469, in handle_exception
    self.raise_uncaught_exception(exc)
  File "/Users/xzr/.virtualenvs/djmyframework/lib/python3.7/site-packages/rest_framework/views.py", line 480, in raise_uncaught_exception
    raise exc
  File "/Users/xzr/.virtualenvs/djmyframework/lib/python3.7/site-packages/rest_framework/views.py", line 506, in dispatch
    response = handler(request, *args, **kwargs)
  File "/Users/xzr/Desktop/pipy/djmyframework/djmyframework/apps/svn_admin/views.py", line 102, in create_svnrepo
    SvnPath.create_svnrepo(svnrepo_name)
  File "/Users/xzr/Desktop/pipy/djmyframework/djmyframework/apps/svn_admin/models.py", line 100, in create_svnrepo
    os.removedirs(svnrepo_conf_path)
  File "/Library/Frameworks/Python.framework/Versions/3.7/lib/python3.7/os.py", line 239, in removedirs
    rmdir(name)
OSError: [Errno 66] Directory not empty: '/Users/xzr/Desktop/svn/asd/conf'

[2021-04-09T17:56:31+0800] [ERROR] [django.request] [pid:54527] [log.py:228] Internal Server Error: /svn_admin/svn_path/create_svnrepo
[2021-04-09T17:59:05+0800] [WARNING] [root] [pid:54574] [middleware.py:81] Traceback (most recent call last):
  File "/Users/xzr/.virtualenvs/djmyframework/lib/python3.7/site-packages/asgiref/sync.py", line 208, in main_wrap
    raise exc_info[1]
  File "/Users/xzr/.virtualenvs/djmyframework/lib/python3.7/site-packages/django/db/models/query.py", line 559, in get_or_create
    return self.get(**kwargs), False
  File "/Users/xzr/.virtualenvs/djmyframework/lib/python3.7/site-packages/django/db/models/query.py", line 417, in get
    self.model._meta.object_name
svn_admin.models.SvnPath.DoesNotExist: SvnPath matching query does not exist.

During handling of the above exception, another exception occurred:

Traceback (most recent call last):
  File "/Users/xzr/.virtualenvs/djmyframework/lib/python3.7/site-packages/django/core/handlers/base.py", line 113, in _get_response
    response = wrapped_callback(request, *callback_args, **callback_kwargs)
  File "/Users/xzr/.virtualenvs/djmyframework/lib/python3.7/site-packages/django/views/decorators/csrf.py", line 54, in wrapped_view
    return view_func(*args, **kwargs)
  File "/Users/xzr/.virtualenvs/djmyframework/lib/python3.7/site-packages/rest_framework/viewsets.py", line 125, in view
    return self.dispatch(request, *args, **kwargs)
  File "/Users/xzr/.virtualenvs/djmyframework/lib/python3.7/site-packages/rest_framework/views.py", line 509, in dispatch
    response = self.handle_exception(exc)
  File "/Users/xzr/.virtualenvs/djmyframework/lib/python3.7/site-packages/rest_framework/views.py", line 469, in handle_exception
    self.raise_uncaught_exception(exc)
  File "/Users/xzr/.virtualenvs/djmyframework/lib/python3.7/site-packages/rest_framework/views.py", line 480, in raise_uncaught_exception
    raise exc
  File "/Users/xzr/.virtualenvs/djmyframework/lib/python3.7/site-packages/rest_framework/views.py", line 506, in dispatch
    response = handler(request, *args, **kwargs)
  File "/Users/xzr/Desktop/pipy/djmyframework/djmyframework/apps/svn_admin/views.py", line 63, in list
    SvnPath.init_svn_projects()
  File "/Users/xzr/Desktop/pipy/djmyframework/djmyframework/apps/svn_admin/models.py", line 157, in init_svn_projects
    svn_paht_model = cls.objects.get_or_create(project_name=project_name, parent=None, path='/')
  File "/Users/xzr/.virtualenvs/djmyframework/lib/python3.7/site-packages/django/db/models/manager.py", line 82, in manager_method
    return getattr(self.get_queryset(), name)(*args, **kwargs)
  File "/Users/xzr/.virtualenvs/djmyframework/lib/python3.7/site-packages/django/db/models/query.py", line 562, in get_or_create
    return self._create_object_from_params(kwargs, params)
  File "/Users/xzr/.virtualenvs/djmyframework/lib/python3.7/site-packages/django/db/models/query.py", line 596, in _create_object_from_params
    obj = self.create(**params)
  File "/Users/xzr/.virtualenvs/djmyframework/lib/python3.7/site-packages/django/db/models/query.py", line 433, in create
    obj.save(force_insert=True, using=self.db)
  File "/Users/xzr/Desktop/pipy/djmyframework/djmyframework/apps/svn_admin/models.py", line 62, in save
    SvnPath.sync_svn_config_file()
  File "/Users/xzr/Desktop/pipy/djmyframework/djmyframework/apps/svn_admin/models.py", line 133, in sync_svn_config_file
    cls.sync_user_to_password_db()
  File "/Users/xzr/Desktop/pipy/djmyframework/djmyframework/apps/svn_admin/models.py", line 172, in sync_user_to_password_db
    password_db.set(user_section_name, user.username, svnuser.password)
AttributeError: 'SvnUser' object has no attribute 'password'

[2021-04-09T17:59:05+0800] [ERROR] [django.request] [pid:54574] [log.py:228] Internal Server Error: /svn_admin/svn_path/list
Traceback (most recent call last):
  File "/Users/xzr/.virtualenvs/djmyframework/lib/python3.7/site-packages/asgiref/sync.py", line 208, in main_wrap
    raise exc_info[1]
  File "/Users/xzr/.virtualenvs/djmyframework/lib/python3.7/site-packages/django/db/models/query.py", line 559, in get_or_create
    return self.get(**kwargs), False
  File "/Users/xzr/.virtualenvs/djmyframework/lib/python3.7/site-packages/django/db/models/query.py", line 417, in get
    self.model._meta.object_name
svn_admin.models.SvnPath.DoesNotExist: SvnPath matching query does not exist.

During handling of the above exception, another exception occurred:

Traceback (most recent call last):
  File "/Users/xzr/.virtualenvs/djmyframework/lib/python3.7/site-packages/django/core/handlers/exception.py", line 34, in inner
    response = get_response(request)
  File "/Users/xzr/.virtualenvs/djmyframework/lib/python3.7/site-packages/django/core/handlers/base.py", line 115, in _get_response
    response = self.process_exception_by_middleware(e, request)
  File "/Users/xzr/.virtualenvs/djmyframework/lib/python3.7/site-packages/django/core/handlers/base.py", line 113, in _get_response
    response = wrapped_callback(request, *callback_args, **callback_kwargs)
  File "/Users/xzr/.virtualenvs/djmyframework/lib/python3.7/site-packages/django/views/decorators/csrf.py", line 54, in wrapped_view
    return view_func(*args, **kwargs)
  File "/Users/xzr/.virtualenvs/djmyframework/lib/python3.7/site-packages/rest_framework/viewsets.py", line 125, in view
    return self.dispatch(request, *args, **kwargs)
  File "/Users/xzr/.virtualenvs/djmyframework/lib/python3.7/site-packages/rest_framework/views.py", line 509, in dispatch
    response = self.handle_exception(exc)
  File "/Users/xzr/.virtualenvs/djmyframework/lib/python3.7/site-packages/rest_framework/views.py", line 469, in handle_exception
    self.raise_uncaught_exception(exc)
  File "/Users/xzr/.virtualenvs/djmyframework/lib/python3.7/site-packages/rest_framework/views.py", line 480, in raise_uncaught_exception
    raise exc
  File "/Users/xzr/.virtualenvs/djmyframework/lib/python3.7/site-packages/rest_framework/views.py", line 506, in dispatch
    response = handler(request, *args, **kwargs)
  File "/Users/xzr/Desktop/pipy/djmyframework/djmyframework/apps/svn_admin/views.py", line 63, in list
    SvnPath.init_svn_projects()
  File "/Users/xzr/Desktop/pipy/djmyframework/djmyframework/apps/svn_admin/models.py", line 157, in init_svn_projects
    svn_paht_model = cls.objects.get_or_create(project_name=project_name, parent=None, path='/')
  File "/Users/xzr/.virtualenvs/djmyframework/lib/python3.7/site-packages/django/db/models/manager.py", line 82, in manager_method
    return getattr(self.get_queryset(), name)(*args, **kwargs)
  File "/Users/xzr/.virtualenvs/djmyframework/lib/python3.7/site-packages/django/db/models/query.py", line 562, in get_or_create
    return self._create_object_from_params(kwargs, params)
  File "/Users/xzr/.virtualenvs/djmyframework/lib/python3.7/site-packages/django/db/models/query.py", line 596, in _create_object_from_params
    obj = self.create(**params)
  File "/Users/xzr/.virtualenvs/djmyframework/lib/python3.7/site-packages/django/db/models/query.py", line 433, in create
    obj.save(force_insert=True, using=self.db)
  File "/Users/xzr/Desktop/pipy/djmyframework/djmyframework/apps/svn_admin/models.py", line 62, in save
    SvnPath.sync_svn_config_file()
  File "/Users/xzr/Desktop/pipy/djmyframework/djmyframework/apps/svn_admin/models.py", line 133, in sync_svn_config_file
    cls.sync_user_to_password_db()
  File "/Users/xzr/Desktop/pipy/djmyframework/djmyframework/apps/svn_admin/models.py", line 172, in sync_user_to_password_db
    password_db.set(user_section_name, user.username, svnuser.password)
AttributeError: 'SvnUser' object has no attribute 'password'
[2021-04-09T17:59:47+0800] [WARNING] [root] [pid:54574] [middleware.py:81] Traceback (most recent call last):
  File "/Users/xzr/.virtualenvs/djmyframework/lib/python3.7/site-packages/django/core/handlers/base.py", line 113, in _get_response
    response = wrapped_callback(request, *callback_args, **callback_kwargs)
  File "/Users/xzr/.virtualenvs/djmyframework/lib/python3.7/site-packages/django/views/decorators/csrf.py", line 54, in wrapped_view
    return view_func(*args, **kwargs)
  File "/Users/xzr/.virtualenvs/djmyframework/lib/python3.7/site-packages/rest_framework/viewsets.py", line 125, in view
    return self.dispatch(request, *args, **kwargs)
  File "/Users/xzr/.virtualenvs/djmyframework/lib/python3.7/site-packages/rest_framework/views.py", line 509, in dispatch
    response = self.handle_exception(exc)
  File "/Users/xzr/.virtualenvs/djmyframework/lib/python3.7/site-packages/rest_framework/views.py", line 469, in handle_exception
    self.raise_uncaught_exception(exc)
  File "/Users/xzr/.virtualenvs/djmyframework/lib/python3.7/site-packages/rest_framework/views.py", line 480, in raise_uncaught_exception
    raise exc
  File "/Users/xzr/.virtualenvs/djmyframework/lib/python3.7/site-packages/rest_framework/views.py", line 506, in dispatch
    response = handler(request, *args, **kwargs)
  File "/Users/xzr/Desktop/pipy/djmyframework/djmyframework/apps/svn_admin/views.py", line 75, in save
    return super(SvnPathSet, self).save(request)
  File "/Users/xzr/Desktop/pipy/djmyframework/djmyframework/framework/views.py", line 468, in save
    serializer, msg = self.save_instance(request)
  File "/Users/xzr/Desktop/pipy/djmyframework/djmyframework/framework/views.py", line 457, in save_instance
    serializer.save(**kwargs)
  File "/Users/xzr/Desktop/pipy/djmyframework/djmyframework/framework/serializer.py", line 224, in save
    super(BaseModelSerializer, self).save(**kwargs)
  File "/Users/xzr/.virtualenvs/djmyframework/lib/python3.7/site-packages/rest_framework/serializers.py", line 200, in save
    self.instance = self.update(self.instance, validated_data)
  File "/Users/xzr/.virtualenvs/djmyframework/lib/python3.7/site-packages/rest_framework/serializers.py", line 983, in update
    instance.save()
  File "/Users/xzr/Desktop/pipy/djmyframework/djmyframework/apps/svn_admin/models.py", line 62, in save
    SvnPath.sync_svn_config_file()
  File "/Users/xzr/Desktop/pipy/djmyframework/djmyframework/apps/svn_admin/models.py", line 133, in sync_svn_config_file
    cls.sync_user_to_password_db()
  File "/Users/xzr/Desktop/pipy/djmyframework/djmyframework/apps/svn_admin/models.py", line 172, in sync_user_to_password_db
    password_db.set(user_section_name, user.username, svnuser.password)
AttributeError: 'SvnUser' object has no attribute 'password'

[2021-04-09T17:59:47+0800] [ERROR] [django.request] [pid:54574] [log.py:228] Internal Server Error: /svn_admin/svn_path/save
[2021-04-09T18:00:15+0800] [WARNING] [root] [pid:54574] [middleware.py:81] Traceback (most recent call last):
  File "/Users/xzr/.virtualenvs/djmyframework/lib/python3.7/site-packages/django/core/handlers/base.py", line 113, in _get_response
    response = wrapped_callback(request, *callback_args, **callback_kwargs)
  File "/Users/xzr/.virtualenvs/djmyframework/lib/python3.7/site-packages/django/views/decorators/csrf.py", line 54, in wrapped_view
    return view_func(*args, **kwargs)
  File "/Users/xzr/.virtualenvs/djmyframework/lib/python3.7/site-packages/rest_framework/viewsets.py", line 125, in view
    return self.dispatch(request, *args, **kwargs)
  File "/Users/xzr/.virtualenvs/djmyframework/lib/python3.7/site-packages/rest_framework/views.py", line 509, in dispatch
    response = self.handle_exception(exc)
  File "/Users/xzr/.virtualenvs/djmyframework/lib/python3.7/site-packages/rest_framework/views.py", line 469, in handle_exception
    self.raise_uncaught_exception(exc)
  File "/Users/xzr/.virtualenvs/djmyframework/lib/python3.7/site-packages/rest_framework/views.py", line 480, in raise_uncaught_exception
    raise exc
  File "/Users/xzr/.virtualenvs/djmyframework/lib/python3.7/site-packages/rest_framework/views.py", line 506, in dispatch
    response = handler(request, *args, **kwargs)
  File "/Users/xzr/Desktop/pipy/djmyframework/djmyframework/apps/svn_admin/views.py", line 75, in save
    return super(SvnPathSet, self).save(request)
  File "/Users/xzr/Desktop/pipy/djmyframework/djmyframework/framework/views.py", line 468, in save
    serializer, msg = self.save_instance(request)
  File "/Users/xzr/Desktop/pipy/djmyframework/djmyframework/framework/views.py", line 457, in save_instance
    serializer.save(**kwargs)
  File "/Users/xzr/Desktop/pipy/djmyframework/djmyframework/framework/serializer.py", line 224, in save
    super(BaseModelSerializer, self).save(**kwargs)
  File "/Users/xzr/.virtualenvs/djmyframework/lib/python3.7/site-packages/rest_framework/serializers.py", line 200, in save
    self.instance = self.update(self.instance, validated_data)
  File "/Users/xzr/.virtualenvs/djmyframework/lib/python3.7/site-packages/rest_framework/serializers.py", line 983, in update
    instance.save()
  File "/Users/xzr/Desktop/pipy/djmyframework/djmyframework/apps/svn_admin/models.py", line 62, in save
    SvnPath.sync_svn_config_file()
  File "/Users/xzr/Desktop/pipy/djmyframework/djmyframework/apps/svn_admin/models.py", line 133, in sync_svn_config_file
    cls.sync_user_to_password_db()
  File "/Users/xzr/Desktop/pipy/djmyframework/djmyframework/apps/svn_admin/models.py", line 172, in sync_user_to_password_db
    password_db.set(user_section_name, user.username, svnuser.raw_password)
AttributeError: 'SvnUser' object has no attribute 'password'

[2021-04-09T18:00:15+0800] [ERROR] [django.request] [pid:54574] [log.py:228] Internal Server Error: /svn_admin/svn_path/save
